Workbook

Sheet Instrucciones
B2: Simulador de empresa de bolsos de cuero — Catalogo maestro de decisiones
B4: Como esta organizado este archivo:
B6: 1) Catalogo_Decisiones: TODAS las opciones posibles del juego. Cada opcion es una fila y cada dato (costo, aporte a cada puntaje) tiene su propia celda — nada esta combinado en una sola celda.
B7: 2) Seleccion_Ciclo0: aqui el jugador elige, por cada grupo de decision (maquinas, personal, canal, etc.), el codigo de la opcion que quiere (lista desplegable en la columna B). Las demas columnas se completan solas con formulas.
B8: 2b) Lotes_Produccion: aqui se decide la calidad POR LOTE, no como promedio de toda la empresa. Cada lote (hasta 3 por ciclo) tiene su propia cantidad de unidades, su propio cuero/accesorios/hilo/molde y su propio segmento de venta. El sistema calcula el Puntaje de Calidad de CADA lote y lo compara contra el segmento elegido (si vendes 'Premium' con insumos bajos, el lote sale 'No alcanza el segmento').
B9: 3) Motor_Puntajes: el Puntaje de Calidad de la empresa es el promedio de los lotes PONDERADO por las unidades de cada uno (un lote de 500 unidades pesa mas que uno de 50). Los otros 3 puntajes (Eficiencia, Reputacion, Salud Financiera) suman los aportes de Seleccion_Ciclo0.
B10: 4) Matriz_Consecuencias: reglas de negocio — que pasa (efecto numerico) y que mensaje ve el jugador segun el valor de cada puntaje.
B12: Celdas amarillas = donde se elige/edita (inputs). Celdas verdes = puntajes/aportes calculados. Celdas grises = fijas u obligatorias.
B14: Para agregar una opcion nueva: agrega una fila en Catalogo_Decisiones con su Codigo unico y sus aportes, y aparecera disponible para elegir en Seleccion_Ciclo0 (agregando el codigo a la lista desplegable del grupo correspondiente).

Sheet DECISIONES
B2: DECISIONES | C2: Puntaje
B3: Depreciación
B4: Garantía del producto
B5: Mantenimiento de maquinaria
B6: Política de inventarios

Sheet Seleccion_Ciclo0
A1: Grupo de decision | B1: Codigo elegido (elige de la lista) | C1: Opcion / Nivel (auto) | D1: Descripcion (auto) | E1: Costo referencial (auto) | F1: Aporte Calidad (auto) | G1: Aporte Eficiencia (auto) | H1: Aporte Reputacion (auto) | I1: Aporte Financiero (auto)
A2: Maquina de ensamblado | B2: INF-03 | C2: {=IFERROR(INDEX(Catalogo_Decisiones!$D$2:$D$57,MATCH($B2,Catalogo_Decisiones!$A$2:$A$57,0)),"")} -> Nivel 2: semi-industrial | D2: {=IFERROR(INDEX(Catalogo_Decisiones!$F$2:$F$57,MATCH($B2,Catalogo_Decisiones!$A$2:$A$57,0)),"")} -> Maquina de coser de columna/brazo (poste) Typical TB-801 | E2: {=IFERROR(INDEX(Catalogo_Decisiones!$G$2:$G$57,MATCH($B2,Catalogo_Decisiones!$A$2:$A$57,0)),0)} -> 7500 | F2: {=IFERROR(INDEX(Catalogo_Decisiones!$H$2:$H$57,MATCH($B2,Catalogo_Decisiones!$A$2:$A$57,0)),0)} -> 2 | G2: {=IFERROR(INDEX(Catalogo_Decisiones!$I$2:$I$57,MATCH($B2,Catalogo_Decisiones!$A$2:$A$57,0)),0)} -> 2 | H2: {=IFERROR(INDEX(Catalogo_Decisiones!$J$2:$J$57,MATCH($B2,Catalogo_Decisiones!$A$2:$A$57,0)),0)} -> 0 | I2: {=IFERROR(INDEX(Catalogo_Decisiones!$K$2:$K$57,MATCH($B2,Catalogo_Decisiones!$A$2:$A$57,0)),0)} -> 0
A3: Maquina de acabados | B3: INF-06 | C3: {=IFERROR(INDEX(Catalogo_Decisiones!$D$2:$D$57,MATCH($B3,Catalogo_Decisiones!$A$2:$A$57,0)),"")} -> Nivel 2: semi-industrial | D3: {=IFERROR(INDEX(Catalogo_Decisiones!$F$2:$F$57,MATCH($B3,Catalogo_Decisiones!$A$2:$A$57,0)),"")} -> Maquina de pulido de bordes (edge burnisher) electrica, tinte con pincel/aerografo | E3: {=IFERROR(INDEX(Catalogo_Decisiones!$G$2:$G$57,MATCH($B3,Catalogo_Decisiones!$A$2:$A$57,0)),0)} -> 4500 | F3: {=IFERROR(INDEX(Catalogo_Decisiones!$H$2:$H$57,MATCH($B3,Catalogo_Decisiones!$A$2:$A$57,0)),0)} -> 2 | G3: {=IFERROR(INDEX(Catalogo_Decisiones!$I$2:$I$57,MATCH($B3,Catalogo_Decisiones!$A$2:$A$57,0)),0)} -> 2 | H3: {=IFERROR(INDEX(Catalogo_Decisiones!$J$2:$J$57,MATCH($B3,Catalogo_Decisiones!$A$2:$A$57,0)),0)} -> 0 | I3: {=IFERROR(INDEX(Catalogo_Decisiones!$K$2:$K$57,MATCH($B3,Catalogo_Decisiones!$A$2:$A$57,0)),0)} -> 0
A4: Molde | B4: INF-09 | C4: {=IFERROR(INDEX(Catalogo_Decisiones!$D$2:$D$57,MATCH($B4,Catalogo_Decisiones!$A$2:$A$57,0)),"")} -> Nivel 2 - Generico mejorado | D4: {=IFERROR(INDEX(Catalogo_Decisiones!$F$2:$F$57,MATCH($B4,Catalogo_Decisiones!$A$2:$A$57,0)),"")} -> Patron tecnico mas elaborado, con lineas de corte, marcado y perforaciones bien definidas | E4: {=IFERROR(INDEX(Catalogo_Decisiones!$G$2:$G$57,MATCH($B4,Catalogo_Decisiones!$A$2:$A$57,0)),0)} -> 1200 | F4: {=IFERROR(INDEX(Catalogo_Decisiones!$H$2:$H$57,MATCH($B4,Catalogo_Decisiones!$A$2:$A$57,0)),0)} -> 2 | G4: {=IFERROR(INDEX(Catalogo_Decisiones!$I$2:$I$57,MATCH($B4,Catalogo_Decisiones!$A$2:$A$57,0)),0)} -> 2 | H4: {=IFERROR(INDEX(Catalogo_Decisiones!$J$2:$J$57,MATCH($B4,Catalogo_Decisiones!$A$2:$A$57,0)),0)} -> 1 | I4: {=IFERROR(INDEX(Catalogo_Decisiones!$K$2:$K$57,MATCH($B4,Catalogo_Decisiones!$A$2:$A$57,0)),0)} -> 0
A5: Personal de corte | B5: RH-02 | C5: {=IFERROR(INDEX(Catalogo_Decisiones!$D$2:$D$57,MATCH($B5,Catalogo_Decisiones!$A$2:$A$57,0)),"")} -> Nivel 2 - Cortador con experiencia | D5: {=IFERROR(INDEX(Catalogo_Decisiones!$F$2:$F$57,MATCH($B5,Catalogo_Decisiones!$A$2:$A$57,0)),"")} -> Optimiza el aprovechamiento del cuero, reduce desperdicio, mas rapido | E5: {=IFERROR(INDEX(Catalogo_Decisiones!$G$2:$G$57,MATCH($B5,Catalogo_Decisiones!$A$2:$A$57,0)),0)} -> 2500 | F5: {=IFERROR(INDEX(Catalogo_Decisiones!$H$2:$H$57,MATCH($B5,Catalogo_Decisiones!$A$2:$A$57,0)),0)} -> 1 | G5: {=IFERROR(INDEX(Catalogo_Decisiones!$I$2:$I$57,MATCH($B5,Catalogo_Decisiones!$A$2:$A$57,0)),0)} -> 2 | H5: {=IFERROR(INDEX(Catalogo_Decisiones!$J$2:$J$57,MATCH($B5,Catalogo_Decisiones!$A$2:$A$57,0)),0)} -> 0 | I5: {=IFERROR(INDEX(Catalogo_Decisiones!$K$2:$K$57,MATCH($B5,Catalogo_Decisiones!$A$2:$A$57,0)),0)} -> 0
A6: Personal de ensamble | B6: RH-05 | C6: {=IFERROR(INDEX(Catalogo_Decisiones!$D$2:$D$57,MATCH($B6,Catalogo_Decisiones!$A$2:$A$57,0)),"")} -> Nivel 2 - Maquinista industrial | D6: {=IFERROR(INDEX(Catalogo_Decisiones!$F$2:$F$57,MATCH($B6,Catalogo_Decisiones!$A$2:$A$57,0)),"")} -> Maquina semi-industrial/industrial, costuras reforzadas, mayor velocidad | E6: {=IFERROR(INDEX(Catalogo_Decisiones!$G$2:$G$57,MATCH($B6,Catalogo_Decisiones!$A$2:$A$57,0)),0)} -> 2800 | F6: {=IFERROR(INDEX(Catalogo_Decisiones!$H$2:$H$57,MATCH($B6,Catalogo_Decisiones!$A$2:$A$57,0)),0)} -> 1 | G6: {=IFERROR(INDEX(Catalogo_Decisiones!$I$2:$I$57,MATCH($B6,Catalogo_Decisiones!$A$2:$A$57,0)),0)} -> 2 | H6: {=IFERROR(INDEX(Catalogo_Decisiones!$J$2:$J$57,MATCH($B6,Catalogo_Decisiones!$A$2:$A$57,0)),0)} -> 0 | I6: {=IFERROR(INDEX(Catalogo_Decisiones!$K$2:$K$57,MATCH($B6,Catalogo_Decisiones!$A$2:$A$57,0)),0)} -> 0
A7: Personal de acabados | B7: RH-08 | C7: {=IFERROR(INDEX(Catalogo_Decisiones!$D$2:$D$57,MATCH($B7,Catalogo_Decisiones!$A$2:$A$57,0)),"")} -> Nivel 2 - Tecnico en acabados | D7: {=IFERROR(INDEX(Catalogo_Decisiones!$F$2:$F$57,MATCH($B7,Catalogo_Decisiones!$A$2:$A$57,0)),"")} -> Maneja maquina de pulido de bordes, tinte con aerografo, resultado consistente | E7: {=IFERROR(INDEX(Catalogo_Decisiones!$G$2:$G$57,MATCH($B7,Catalogo_Decisiones!$A$2:$A$57,0)),0)} -> 2800 | F7: {=IFERROR(INDEX(Catalogo_Decisiones!$H$2:$H$57,MATCH($B7,Catalogo_Decisiones!$A$2:$A$57,0)),0)} -> 1 | G7: {=IFERROR(INDEX(Catalogo_Decisiones!$I$2:$I$57,MATCH($B7,Catalogo_Decisiones!$A$2:$A$57,0)),0)} -> 2 | H7: {=IFERROR(INDEX(Catalogo_Decisiones!$J$2:$J$57,MATCH($B7,Catalogo_Decisiones!$A$2:$A$57,0)),0)} -> 0 | I7: {=IFERROR(INDEX(Catalogo_Decisiones!$K$2:$K$57,MATCH($B7,Catalogo_Decisiones!$A$2:$A$57,0)),0)} -> 0
A8: Jefatura | B8: RH-10A | C8: {=IFERROR(INDEX(Catalogo_Decisiones!$D$2:$D$57,MATCH($B8,Catalogo_Decisiones!$A$2:$A$57,0)),"")} -> Contratar jefatura | D8: {=IFERROR(INDEX(Catalogo_Decisiones!$F$2:$F$57,MATCH($B8,Catalogo_Decisiones!$A$2:$A$57,0)),"")} -> Coordina el equipo, reduce riesgo de descoordinacion | E8: {=IFERROR(INDEX(Catalogo_Decisiones!$G$2:$G$57,MATCH($B8,Catalogo_Decisiones!$A$2:$A$57,0)),0)} -> 3000 | F8: {=IFERROR(INDEX(Catalogo_Decisiones!$H$2:$H$57,MATCH($B8,Catalogo_Decisiones!$A$2:$A$57,0)),0)} -> 0 | G8: {=IFERROR(INDEX(Catalogo_Decisiones!$I$2:$I$57,MATCH($B8,Catalogo_Decisiones!$A$2:$A$57,0)),0)} -> 2 | H8: {=IFERROR(INDEX(Catalogo_Decisiones!$J$2:$J$57,MATCH($B8,Catalogo_Decisiones!$A$2:$A$57,0)),0)} -> 1 | I8: {=IFERROR(INDEX(Catalogo_Decisiones!$K$2:$K$57,MATCH($B8,Catalogo_Decisiones!$A$2:$A$57,0)),0)} -> 0
A9: Canal de venta | B9: COM-01C | C9: {=IFERROR(INDEX(Catalogo_Decisiones!$D$2:$D$57,MATCH($B9,Catalogo_Decisiones!$A$2:$A$57,0)),"")} -> Web y fisico | D9: {=IFERROR(INDEX(Catalogo_Decisiones!$F$2:$F$57,MATCH($B9,Catalogo_Decisiones!$A$2:$A$57,0)),"")} -> Mayor cobertura y demanda; incrementa complejidad y costo | E9: {=IFERROR(INDEX(Catalogo_Decisiones!$G$2:$G$57,MATCH($B9,Catalogo_Decisiones!$A$2:$A$57,0)),0)} -> 1500 | F9: {=IFERROR(INDEX(Catalogo_Decisiones!$H$2:$H$57,MATCH($B9,Catalogo_Decisiones!$A$2:$A$57,0)),0)} -> 0 | G9: {=IFERROR(INDEX(Catalogo_Decisiones!$I$2:$I$57,MATCH($B9,Catalogo_Decisiones!$A$2:$A$57,0)),0)} -> 0 | H9: {=IFERROR(INDEX(Catalogo_Decisiones!$J$2:$J$57,MATCH($B9,Catalogo_Decisiones!$A$2:$A$57,0)),0)} -> 2 | I9: {=IFERROR(INDEX(Catalogo_Decisiones!$K$2:$K$57,MATCH($B9,Catalogo_Decisiones!$A$2:$A$57,0)),0)} -> -1
A10: Acceso a prestamo bancario | B10: FIN-01B | C10: {=IFERROR(INDEX(Catalogo_Decisiones!$D$2:$D$57,MATCH($B10,Catalogo_Decisiones!$A$2:$A$57,0)),"")} -> No solicitar prestamo | D10: {=IFERROR(INDEX(Catalogo_Decisiones!$F$2:$F$57,MATCH($B10,Catalogo_Decisiones!$A$2:$A$57,0)),"")} -> Evita intereses; la expansion depende del capital propio | E10: {=IFERROR(INDEX(Catalogo_Decisiones!$G$2:$G$57,MATCH($B10,Catalogo_Decisiones!$A$2:$A$57,0)),0)} -> 0 | F10: {=IFERROR(INDEX(Catalogo_Decisiones!$H$2:$H$57,MATCH($B10,Catalogo_Decisiones!$A$2:$A$57,0)),0)} -> 0 | G10: {=IFERROR(INDEX(Catalogo_Decisiones!$I$2:$I$57,MATCH($B10,Catalogo_Decisiones!$A$2:$A$57,0)),0)} -> 0 | H10: {=IFERROR(INDEX(Catalogo_Decisiones!$J$2:$J$57,MATCH($B10,Catalogo_Decisiones!$A$2:$A$57,0)),0)} -> 1 | I10: {=IFERROR(INDEX(Catalogo_Decisiones!$K$2:$K$57,MATCH($B10,Catalogo_Decisiones!$A$2:$A$57,0)),0)} -> 1
A11: Numero de proveedores | B11: INS-09B | C11: {=IFERROR(INDEX(Catalogo_Decisiones!$D$2:$D$57,MATCH($B11,Catalogo_Decisiones!$A$2:$A$57,0)),"")} -> Varios proveedores | D11: {=IFERROR(INDEX(Catalogo_Decisiones!$F$2:$F$57,MATCH($B11,Catalogo_Decisiones!$A$2:$A$57,0)),"")} -> Menor descuento, pero reduce el riesgo de desabastecimiento | E11: {=IFERROR(INDEX(Catalogo_Decisiones!$G$2:$G$57,MATCH($B11,Catalogo_Decisiones!$A$2:$A$57,0)),0)} -> 0 | F11: {=IFERROR(INDEX(Catalogo_Decisiones!$H$2:$H$57,MATCH($B11,Catalogo_Decisiones!$A$2:$A$57,0)),0)} -> 0 | G11: {=IFERROR(INDEX(Catalogo_Decisiones!$I$2:$I$57,MATCH($B11,Catalogo_Decisiones!$A$2:$A$57,0)),0)} -> 1 | H11: {=IFERROR(INDEX(Catalogo_Decisiones!$J$2:$J$57,MATCH($B11,Catalogo_Decisiones!$A$2:$A$57,0)),0)} -> 0 | I11: {=IFERROR(INDEX(Catalogo_Decisiones!$K$2:$K$57,MATCH($B11,Catalogo_Decisiones!$A$2:$A$57,0)),0)} -> 0
A12: Politica de pago a proveedores | B12: INS-10A | C12: {=IFERROR(INDEX(Catalogo_Decisiones!$D$2:$D$57,MATCH($B12,Catalogo_Decisiones!$A$2:$A$57,0)),"")} -> Contado | D12: {=IFERROR(INDEX(Catalogo_Decisiones!$F$2:$F$57,MATCH($B12,Catalogo_Decisiones!$A$2:$A$57,0)),"")} -> Obtiene 3% de descuento; reduce la caja inmediatamente | E12: {=IFERROR(INDEX(Catalogo_Decisiones!$G$2:$G$57,MATCH($B12,Catalogo_Decisiones!$A$2:$A$57,0)),0)} -> 0 | F12: {=IFERROR(INDEX(Catalogo_Decisiones!$H$2:$H$57,MATCH($B12,Catalogo_Decisiones!$A$2:$A$57,0)),0)} -> 0 | G12: {=IFERROR(INDEX(Catalogo_Decisiones!$I$2:$I$57,MATCH($B12,Catalogo_Decisiones!$A$2:$A$57,0)),0)} -> 0 | H12: {=IFERROR(INDEX(Catalogo_Decisiones!$J$2:$J$57,MATCH($B12,Catalogo_Decisiones!$A$2:$A$57,0)),0)} -> 0 | I12: {=IFERROR(INDEX(Catalogo_Decisiones!$K$2:$K$57,MATCH($B12,Catalogo_Decisiones!$A$2:$A$57,0)),0)} -> -1
A13: Lead time | B13: INS-11B | C13: {=IFERROR(INDEX(Catalogo_Decisiones!$D$2:$D$57,MATCH($B13,Catalogo_Decisiones!$A$2:$A$57,0)),"")} -> Normal - 7 dias | D13: {=IFERROR(INDEX(Catalogo_Decisiones!$F$2:$F$57,MATCH($B13,Catalogo_Decisiones!$A$2:$A$57,0)),"")} -> Equilibrio entre costo y disponibilidad | E13: {=IFERROR(INDEX(Catalogo_Decisiones!$G$2:$G$57,MATCH($B13,Catalogo_Decisiones!$A$2:$A$57,0)),0)} -> 0 | F13: {=IFERROR(INDEX(Catalogo_Decisiones!$H$2:$H$57,MATCH($B13,Catalogo_Decisiones!$A$2:$A$57,0)),0)} -> 0 | G13: {=IFERROR(INDEX(Catalogo_Decisiones!$I$2:$I$57,MATCH($B13,Catalogo_Decisiones!$A$2:$A$57,0)),0)} -> 0 | H13: {=IFERROR(INDEX(Catalogo_Decisiones!$J$2:$J$57,MATCH($B13,Catalogo_Decisiones!$A$2:$A$57,0)),0)} -> 0 | I13: {=IFERROR(INDEX(Catalogo_Decisiones!$K$2:$K$57,MATCH($B13,Catalogo_Decisiones!$A$2:$A$57,0)),0)} -> 0
... A15: Inversion en marketing | B15: INV-02B | C15: {=IFERROR(INDEX(Catalogo_Decisiones!$D$2:$D$57,MATCH($B15,Catalogo_Decisiones!$A$2:$A$57,0)),"")} -> Media | D15: {=IFERROR(INDEX(Catalogo_Decisiones!$F$2:$F$57,MATCH($B15,Catalogo_Decisiones!$A$2:$A$57,0)),"")} -> S/ 6,000 por ciclo; aumenta demanda estimada 12% y reputacion | E15: {=IFERROR(INDEX(Catalogo_Decisiones!$G$2:$G$57,MATCH($B15,Catalogo_Decisiones!$A$2:$A$57,0)),0)} -> 6000 | F15: {=IFERROR(INDEX(Catalogo_Decisiones!$H$2:$H$57,MATCH($B15,Catalogo_Decisiones!$A$2:$A$57,0)),0)} -> 0 | G15: {=IFERROR(INDEX(Catalogo_Decisiones!$I$2:$I$57,MATCH($B15,Catalogo_Decisiones!$A$2:$A$57,0)),0)} -> 0 | H15: {=IFERROR(INDEX(Catalogo_Decisiones!$J$2:$J$57,MATCH($B15,Catalogo_Decisiones!$A$2:$A$57,0)),0)} -> 2 | I15: {=IFERROR(INDEX(Catalogo_Decisiones!$K$2:$K$57,MATCH($B15,Catalogo_Decisiones!$A$2:$A$57,0)),0)} -> -1
A16: --- Otras decisiones numericas ---
A17: PRO-01 - Cantidad inicial a producir (unidades) | B17: 0
A18: COM-02 - N° de tiendas en zona alta (Miraflores) | B18: 0
A19: COM-03 - N° de tiendas en zona media (Los Olivos / San Miguel) | B19: 0
A20: COM-04 - N° de tiendas en zona baja (SJL / SMP) | B20: 0
A21: COM-05N - % de ventas a credito (0-100) | B21: 0
A22: FIN-01M - Monto de prestamo solicitado (S/) | B22: 0

Sheet Catalogo_Decisiones
A1: Codigo | B1: Bloque | C1: Grupo de decision | D1: Opcion / Nivel | E1: Permanencia | F1: Descripcion | G1: Costo referencial (S/) | H1: Aporte Calidad | I1: Aporte Eficiencia | J1: Aporte Reputacion | K1: Aporte Financiero | L1: Notas
A2: GEN-01 | B2: A. Empresa | C2: Razon social | D2: Texto libre | E2: Fija | F2: Nombre legal de la empresa (texto) | G2: 0 | H2: 0 | I2: 0 | J2: 0 | K2: 0 | L2: Sin efecto en puntajes
A3: GEN-02 | B3: A. Empresa | C3: Nombre comercial / marca | D3: Texto libre | E3: Fija | F3: Marca comercial (texto) | G3: 0 | H3: 0 | I3: 0 | J3: 0 | K3: 0 | L3: Sin efecto en puntajes
A4: GEN-04 | B4: A. Empresa | C4: Tipos de bolsos | D4: Texto libre | E4: Fija | F4: Linea de productos que fabrica (tote, cartera, mochila, etc.) | G4: 0 | H4: 0 | I4: 0 | J4: 0 | K4: 0 | L4: Sin efecto en puntajes
A5: SEG-01 | B5: A. Empresa | C5: Segmento / linea | D5: Economico | E5: Fija | F5: Precio bajo, prioriza volumen y costo | G5: 0 | H5: 0 | I5: 0 | J5: 1 | K5: 0 | L5: Exige coherencia con Calidad real
A6: SEG-02 | B6: A. Empresa | C6: Segmento / linea | D6: Estandar | E6: Fija | F6: Equilibra costo, calidad, demanda y margen | G6: 0 | H6: 1 | I6: 0 | J6: 1 | K6: 0
A7: SEG-03 | B7: A. Empresa | C7: Segmento / linea | D7: Premium | E7: Fija | F7: Precio alto; requiere Calidad>=7 para sostenerse | G7: 0 | H7: 2 | I7: 0 | J7: 2 | K7: 0 | L7: Riesgo si Calidad interna es baja (ver Matriz)
A8: INF-01 | B8: B. Infraestructura | C8: Mesa de corte | D8: Unica (obligatoria) | E8: Fija | F8: Inversion fija para todos; habilita la etapa de corte | G8: 2500 | H8: 0 | I8: 1 | J8: 0 | K8: 0 | L8: Obligatoria, no otorga niveles
A9: INF-02 | B9: B. Infraestructura | C9: Maquina de ensamblado | D9: Nivel 1: manual/basica | E9: Fija | F9: Costura Singer 4423 Heavy Duty; desbastadora a mano con cuchilla o lija | G9: 3500 | H9: 1 | I9: 1 | J9: 0 | K9: 0
A10: INF-03 | B10: B. Infraestructura | C10: Maquina de ensamblado | D10: Nivel 2: semi-industrial | E10: Fija | F10: Maquina de coser de columna/brazo (poste) Typical TB-801 | G10: 7500 | H10: 2 | I10: 2 | J10: 0 | K10: 0
A11: INF-04 | B11: B. Infraestructura | C11: Maquina de ensamblado | D11: Nivel 3: industrial | E11: Fija | F11: Juki de triple accionamiento; desbastadora automatica de alta precision, servomotor | G11: 15000 | H11: 3 | I11: 3 | J11: 0 | K11: 0
A12: INF-05 | B12: B. Infraestructura | C12: Maquina de acabados | D12: Nivel 1: manual/basica | E12: Fija | F12: Acabado a mano con cera/tinte de bordes, bruñido manual. Lento, variable en calidad | G12: 1200 | H12: 1 | I12: 1 | J12: 0 | K12: 0
A13: INF-06 | B13: B. Infraestructura | C13: Maquina de acabados | D13: Nivel 2: semi-industrial | E13: Fija | F13: Maquina de pulido de bordes (edge burnisher) electrica, tinte con pincel/aerografo | G13: 4500 | H13: 2 | I13: 2 | J13: 0 | K13: 0
A14: INF-07 | B14: B. Infraestructura | C14: Maquina de acabados | D14: Nivel 3: industrial | E14: Fija | F14: Linea de acabado con teñido automatico + pulido, control de temperatura y velocidad | G14: 9500 | H14: 3 | I14: 3 | J14: 0 | K14: 0
A15: INF-08 | B15: B. Infraestructura | C15: Molde | D15: Nivel 1 - Generico basico | E15: Fija | F15: Patrones simples, tipo plantilla estandar de internet o catalogo generico | G15: 300 | H15: 1 | I15: 1 | J15: 0 | K15: 0 | L15: Bajo aprovechamiento de cuero
A16: INF-09 | B16: B. Infraestructura | C16: Molde | D16: Nivel 2 - Generico mejorado | E16: Fija | F16: Patron tecnico mas elaborado, con lineas de corte, marcado y perforaciones bien definidas | G16: 1200 | H16: 2 | I16: 2 | J16: 1 | K16: 0 | L16: Aprovechamiento medio-alto
A17: INF-10 | B17: B. Infraestructura | C17: Molde | D17: Nivel 3 - Premium | E17: Fija | F17: La empresa desarrolla su propio patron desde cero, adaptado a su propuesta de marca | G17: 3500 | H17: 4 | I17: 2 | J17: 2 | K17: 0 | L17: Maximo aprovechamiento y diferenciacion
A18: RH-01 | B18: C. RRHH | C18: Personal de corte | D18: Nivel 1 - Operario basico | E18: Revisable con costo | F18: Corta con plantilla simple, sin experiencia previa. Mas lento, mas margen de error | G18: 1500 | H18: 0 | I18: 1 | J18: 0 | K18: 0
A19: RH-02 | B19: C. RRHH | C19: Personal de corte | D19: Nivel 2 - Cortador con experiencia | E19: Revisable con costo | F19: Optimiza el aprovechamiento del cuero, reduce desperdicio, mas rapido | G19: 2500 | H19: 1 | I19: 2 | J19: 0 | K19: 0
A20: RH-03 | B20: C. RRHH | C20: Personal de corte | D20: Nivel 3 - Maestro cortador | E20: Revisable con costo | F20: Trabaja cueros irregulares/premium, maximo aprovechamiento, minimo desperdicio | G20: 4000 | H20: 2 | I20: 3 | J20: 0 | K20: 0
A21: RH-04 | B21: C. RRHH | C21: Personal de ensamble | D21: Nivel 1 - Costurero basico | E21: Revisable con costo | F21: Maquina domestica, puntadas rectas simples, funciona con diseños sencillos | G21: 1500 | H21: 0 | I21: 1 | J21: 0 | K21: 0
A22: RH-05 | B22: C. RRHH | C22: Personal de ensamble | D22: Nivel 2 - Maquinista industrial | E22: Revisable con costo | F22: Maquina semi-industrial/industrial, costuras reforzadas, mayor velocidad | G22: 2800 | H22: 1 | I22: 2 | J22: 0 | K22: 0
A23: RH-06 | B23: C. RRHH | C23: Personal de ensamble | D23: Nivel 3 - Marroquinero especializado | E23: Revisable con costo | F23: Costura a mano de alta gama, ejecuta moldes exclusivos complejos, ideal linea premium | G23: 4500 | H23: 2 | I23: 3 | J23: 1 | K23: 0
A24: RH-07 | B24: C. RRHH | C24: Personal de acabados | D24: Nivel 1 - Operario de acabado basico | E24: Revisable con costo | F24: Aplica tinte y cera de forma simple, resultado variable | G24: 1500 | H24: 0 | I24: 1 | J24: 0 | K24: 0
A25: RH-08 | B25: C. RRHH | C25: Personal de acabados | D25: Nivel 2 - Tecnico en acabados | E25: Revisable con costo | F25: Maneja maquina de pulido de bordes, tinte con aerografo, resultado consistente | G25: 2800 | H25: 1 | I25: 2 | J25: 0 | K25: 0
A26: RH-09 | B26: C. RRHH | C26: Personal de acabados | D26: Nivel 3 - Artesano acabador | E26: Revisable con costo | F26: Bruñido fino, dorado, decoracion compleja (pedreria, herrajes especiales) | G26: 4500 | H26: 2 | I26: 3 | J26: 1 | K26: 0
A27: RH-10A | B27: C. RRHH | C27: Jefatura | D27: Contratar jefatura | E27: Revisable con costo | F27: Coordina el equipo, reduce riesgo de descoordinacion | G27: 3000 | H27: 0 | I27: 2 | J27: 1 | K27: 0
A28: RH-10B | B28: C. RRHH | C28: Jefatura | D28: No contratar jefatura | E28: Revisable con costo | F28: Ahorra costo fijo, pero aumenta el riesgo de descoordinacion | G28: 0 | H28: 0 | I28: -1 | J28: 0 | K28: 1 | L28: Ahorro de caja pero baja Eficiencia
A29: RH-11 | B29: C. RRHH | C29: Limpieza y servicios generales | D29: Unica (obligatoria) | E29: Fija | F29: Monto fijo obligatorio para mantener la operacion | G29: 600 | H29: 0 | I29: 0 | J29: 0 | K29: 0
A30: RH-12 | B30: C. RRHH | C30: Local de produccion | D30: Estandar (unico) | E30: Fija | F30: Local de produccion estandar; alquiler fijo igual para todos los equipos | G30: 2000 | H30: 0 | I30: 0 | J30: 0 | K30: 0
A31: COM-01A | B31: D. Canales | C31: Canal de venta | D31: Solo tienda fisica | E31: Revisable cada ciclo | F31: Menor cobertura y demanda; menor complejidad y costo | G31: 0 | H31: 0 | I31: 0 | J31: 0 | K31: 1
A32: COM-01B | B32: D. Canales | C32: Canal de venta | D32: Solo web | E32: Revisable cada ciclo | F32: Cobertura amplia con menor costo fijo; depende de marketing digital | G32: 500 | H32: 0 | I32: 0 | J32: 1 | K32: 0
A33: COM-01C | B33: D. Canales | C33: Canal de venta | D33: Web y fisico | E33: Revisable cada ciclo | F33: Mayor cobertura y demanda; incrementa complejidad y costo | G33: 1500 | H33: 0 | I33: 0 | J33: 2 | K33: -1
A34: FIN-01A | B34: D. Canales | C34: Acceso a prestamo bancario | D34: Solicitar prestamo | E34: Fija: habilita | F34: Habilita apalancamiento; permite invertir mas rapido | G34: 0 | H34: 0 | I34: 0 | J34: 0 | K34: -1 | L34: Aumenta apalancamiento
A35: FIN-01B | B35: D. Canales | C35: Acceso a prestamo bancario | D35: No solicitar prestamo | E35: Fija: habilita | F35: Evita intereses; la expansion depende del capital propio | G35: 0 | H35: 0 | I35: 0 | J35: 1 | K35: 1
A36: INS-01 | B36: E. Insumos | C36: Calidad del cuero | D36: Nivel 1 - Cuero sintetico | E36: Revisable cada ciclo | F36: Bajo costo, menor durabilidad, acabado menos premium | G36: 25 | H36: 1 | I36: 0 | J36: 0 | K36: 1 | L36: por unidad, referencial
A37: INS-02 | B37: E. Insumos | C37: Calidad del cuero | D37: Nivel 2 - Cuero genuino estandar | E37: Revisable cada ciclo | F37: Costo medio, durabilidad media | G37: 45 | H37: 2 | I37: 0 | J37: 0 | K37: 0 | L37: por unidad, referencial
A38: INS-03 | B38: E. Insumos | C38: Calidad del cuero | D38: Nivel 3 - Cuero genuino premium | E38: Revisable cada ciclo | F38: Full grain / curtido vegetal: alto costo, alta durabilidad, mejor acabado | G38: 80 | H38: 3 | I38: 0 | J38: 1 | K38: -1 | L38: por unidad, referencial
A39: INS-04 | B39: E. Insumos | C39: Calidad de accesorios | D39: Nivel 1 - Aleacion economica | E39: Revisable cada ciclo | F39: Bajo costo, se oxida/desgasta mas rapido | G39: 4 | H39: 1 | I39: 0 | J39: 0 | K39: 1 | L39: por unidad, referencial
A40: INS-05 | B40: E. Insumos | C40: Calidad de accesorios | D40: Nivel 2 - Metal premium | E40: Revisable cada ciclo | F40: Laton macizo o acero inoxidable, alto costo, mayor durabilidad y brillo | G40: 9 | H40: 2 | I40: 0 | J40: 1 | K40: -1 | L40: por unidad, referencial
...

Sheet FlujoWeb
B3: Flujo
B4: Steps | C4: Docente | D4: Jugadores | H4: Valeria y Gonzalo
B5: 1 | C5: Launcher | H5: Erick y Miguel
B6: 2 | C6: Login | E6: Se valida el codigo de sala y el nombre empresa(usuario)
B7: 3 | C7: Configuracion del juego (incluye Creacion de Sala)
B8: 4 | D8: Launcher
B9: 5 | D9: Login
B10: 6 | D10: Tutorial | E10: Indicaciones en un carrusel.
A11: Ciclo 1 | B11: 7 | D11: Decisiones
B12: 8 | D12: Espera (Fin de ciclo) | E12: El docente define si se hace automatico o manual
B13: 9 | C13: Información en vivo de las decisiones de los jugadores (Manual: Cierra el ciclo)
B14: 10 | C14: Estados financieros Generales | D14: Estados financieros Individuales e Informacion del mercado | E14: Descargables en pdf
A15: Ciclo 2 | B15: 11 | D15: Decisiones
B16: 12 | D16: Espera (Fin de ciclo)
B17: 13 | C17: Información en vivo de las decisiones de los jugadores (Manual: Cierra el ciclo)
B18: 14 | C18: Estados financieros Generales | D18: Estados financieros Individuales e Informacion del mercado | E18: Descargables en pdf
A19: Ciclo 3 | B19: 15 | D19: Decisiones
B20: 16 | D20: Espera (Fin de ciclo)
B21: 17 | C21: Información en vivo de las decisiones de los jugadores (Manual: Cierra el ciclo)
B22: 18 | C22: Estados financieros Generales | D22: Estados financieros Individuales e Informacion del mercado | E22: Descargables en pdf
A23: Ciclo N | B23: 15 | D23: Decisiones
B24: 16 | D24: Espera (Fin de ciclo)
B25: 17 | C25: Información en vivo de las decisiones de los jugadores (Manual: Cierra el ciclo)
B26: 18 | C26: Estados financieros Generales | D26: Estados financieros Individuales e Informacion del mercado
B27: 23 | C27: Resumen General - Indicar podio | D27: Estados financieros Individuales y Consolidado Final | E27: Descargables en pdf
B28: 24 | D28: Mostrar Podio | E28: Agregar disclaimer indicando que los datos se guardaran un maximo de 24 horas
B37: Si el jugador no tomo decision dentro del tiempo establecido y es la primera decisión se le elimina del juego
B38: El Docente tiene la opcion de eliminar jugadores en cualquier momento. Sin importar si es manual o automatico
B39: Si el jugador no tomo decisiones dentro del tiempo establecido y no es la primera decisión el sistema replica las decisiones del ciclo anterior.

Sheet CANTIDAD DE PRODUCCIÓN
A1: Calculo de MO
A3: AREA DE CORTE
E4: Bolsas por día | F4: Mesa de corte | K4: Producción por día | L4: AL MES | M4: Eficiencia | N4: Produccion Real
C5: Nivel 1 - Operario basico | E5: 5 | F5: 1 | I5: =E5*F5 -> 5 | K5: =MIN(I8,I14,I20) -> 17.2 | L5: =K5*24 -> 412.8 | M5: =K7+(F7+F13+F19)/100+4%*F21 -> 0.96 | N5: =ROUND(L5*M5,0) -> 396 | O5: Esta produccion no puede ser superior a lo que permite el material
C6: Nivel 2 - Cortador con experiencia | E6: 7 | F6: 1 | I6: =E6*F6 -> 7 | K6: Eficiencia BASE
C7: Nivel 3 - Maestro cortador | E7: 9 | F7: 1 | I7: =E7*F7 -> 9 | K7: 0.9
A8: AREA DE ENSAMBLADO | I8: =SUM(I5:I7) -> 21
C9: Operarios | F9: MAQUINARIA MANUAL | G9: MAQUINARIA SEMIINDUSTRIAL | H9: MAQUINARIA INDUSTRIAL | K9: Total de trabajadores | L9: =SUM(F5:F7,F11:H13,F17:H19) -> 8
F10: 1 | G10: 1.2 | H10: 1.5 | K10: total de trabajadores N3 | L10: =SUM(F7,F13:H13,F19:H19) -> 3 | M10: =L10/L9 -> 0.375
C11: Nivel 1 | E11: 6 | H11: 1 | I11: =SUM(F11*E11*$F$10,G11*E11*$G$10,H11*E11*$H$10) -> 9
C12: Nivel 2 | E12: 8 | F12: 1 | G12: 0 | I12: =SUM(F12*E12*$F$10,G12*E12*$G$10,H12*E12*$H$10) -> 8
C13: Nivel 3 | E13: 12 | G13: 1 | I13: =SUM(F13*E13*$F$10,G13*E13*$G$10,H13*E13*$H$10) -> 14.4
A14: AREA DE ACABADO | I14: =SUM(I11:I13) -> 31.4
C15: Operarios | F15: MAQUINARIA MANUAL | G15: MAQUINARIA SEMIINDUSTRIAL | H15: MAQUINARIA INDUSTRIAL
F16: 1 | G16: 1.2 | H16: 1.5
C17: Nivel 1 | E17: 6 | G17: 1 | I17: =SUM(F17*E17*$F$16,G17*E17*$G$16,H17*E17*$H$16) -> 7.2
C18: Nivel 2 | E18: 7 | G18: 0 | H18: 0 | I18: =SUM(F18*E18*$F$16,G18*E18*$G$16,H18*E18*$H$16) -> 0
C19: Nivel 3 | E19: 10 | F19: 1 | I19: =SUM(F19*E19*$F$16,G19*E19*$G$16,H19*E19*$H$16) -> 10
I20: =SUM(I17:I19) -> 17.2
A21: Jefe de Produccion | F21: 1
B23: NOTA: EL PROCETANJE DE TRABAJADORES DE NIVEL 3 AFECTA POSITIVAMENTE A LA EFICIENCIA
A25: Calculo de MP
D27: Calidad del cuero | E27: Calidad del cuero | F27: Calidad del cuero | G27: Calidad de accesorios | H27: Calidad de accesorios | I27: Calidad de accesorios | J27: Calidad del hilo | K27: Calidad del hilo | L27: Calidad del hilo
D28: Nivel 1 - Cuero sintetico | E28: Nivel 2 - Cuero genuino estandar | F28: Nivel 3 - Cuero genuino premium | G28: Nivel 1 - Aleacion economica | H28: Nivel 2 - Metal premium | I28: Nivel 3 - Metal Deluxe | J28: Nivel 1 - Poliester estandar | K28: Nivel 2 - Encerado reforzado | L28: Nivel 3 - Alta tenacidad (nylon trenzado)
C29: UM Compra | D29: rollo | E29: Piel completa | F29: Piel completa | G29: Juego | H29: Juego | I29: Juego | J29: Carrete | K29: Carrete | L29: Carrete
C30: UM Produccion | D30: m2 | E30: m2 | F30: m2 | G30: unidad | H30: unidad | I30: unidad | J30: metro | K30: metro | L30: metro
C31: Nivel 1 - Generico basico | D31: 0.3 | G31: 1 | J31: 6
C32: Nivel 2 - Generico mejorado | E32: 0.4 | H32: 1 | K32: 7
C33: Nivel 3 - Premium | F33: 0.7 | I33: 1 | L33: 13
E35: =N5 -> 396
C36: Cantidad que desea producir | D36: =SUM(D37:D39) -> 520 | E36: =SUM(E37:E39) -> 395
C37: Nivel 1 - Generico basico | D37: 250 | E37: =ROUNDDOWN(D37*E35/D36,0) -> 190
C38: Nivel 2 - Generico mejorado | D38: 180 | E38: =ROUNDDOWN(D38*E35/D36,0) -> 137
C39: Nivel 3 - Premium | D39: 90 | E39: =ROUNDDOWN(D39*E35/D36,0) -> 68
D40: Calidad del cuero | E40: Calidad del cuero | F40: Calidad del cuero | G40: Calidad de accesorios | H40: Calidad de accesorios | I40: Calidad de accesorios | J40: Calidad del hilo | K40: Calidad del hilo | L40: Calidad del hilo
D41: Nivel 1 - Cuero sintetico | E41: Nivel 2 - Cuero genuino estandar | F41: Nivel 3 - Cuero genuino premium | G41: Nivel 1 - Aleacion economica | H41: Nivel 2 - Metal premium | I41: Nivel 3 - Metal Deluxe | J41: Nivel 1 - Poliester estandar | K41: Nivel 2 - Encerado reforzado | L41: Nivel 3 - Alta tenacidad (nylon trenzado)
C42: Nivel 1 - Generico basico | D42: =$D37*D31 -> 75 | E42: =$D37*E31 -> 0 | F42: =$D37*F31 -> 0 | G42: =$D37*G31 -> 250 | H42: =$D37*H31 -> 0 | I42: =$D37*I31 -> 0 | J42: =$D37*J31 -> 1500 | K42: =$D37*K31 -> 0 | L42: =$D37*L31 -> 0
C43: Nivel 2 - Generico mejorado | D43: =$D38*D32 -> 0 | E43: =$D38*E32 -> 72 | F43: =$D38*F32 -> 0 | G43: =$D38*G32 -> 0 | H43: =$D38*H32 -> 180 | I43: =$D38*I32 -> 0 | J43: =$D38*J32 -> 0 | K43: =$D38*K32 -> 1260 | L43: =$D38*L32 -> 0
C44: Nivel 3 - Premium | D44: =$D39*D33 -> 0 | E44: =$D39*E33 -> 0 | F44: =$D39*F33 -> 63 | G44: =$D39*G33 -> 0 | H44: =$D39*H33 -> 0 | I44: =$D39*I33 -> 90 | J44: =$D39*J33 -> 0 | K44: =$D39*K33 -> 0 | L44: =$D39*L33 -> 1170
D47: Calidad del cuero | E47: Calidad del cuero | F47: Calidad del cuero | G47: Calidad de accesorios | H47: Calidad de accesorios | I47: Calidad de accesorios | J47: Calidad del hilo | K47: Calidad del hilo | L47: Calidad del hilo
...

Sheet Costos De Producción
A1: Calculo de MO
T2: Costos: MO
A3: AREA DE CORTE
E4: Bolsas por día | F4: Mesa de corte | K4: Producción por día | L4: AL MES | M4: Eficiencia | N4: Produccion Real | T4: O.Basico | U4: MYPE | V4: NoMype | X4: Costurero básico | Y4: MYPE | Z4: NoMype | AB4: Operario de acabado clásico | AC4: MYPE | AD4: NoMype
C5: Nivel 1 - Operario basico | E5: 6 | F5: 1 | I5: =E5*F5 -> 6 | K5: =MIN(I8,I14,I20) -> 14 | L5: =K5*30 -> 420 | M5: =K7+(F7+F13+F19)/100+4%*F21 -> 0.91 | N5: =ROUND(L5*M5,0) -> 382 | O5: Esta produccion no puede ser superior a lo que permite el material | T5: Sueldo base | U5: 1500 | V5: 1500 | X5: Sueldo base | Y5: 1500 | Z5: 1500 | AB5: Sueldo base | AC5: 1500 | AD5: 1500
C6: Nivel 2 - Cortador con experiencia | E6: 8 | F6: 1 | I6: =E6*F6 -> 8 | K6: Eficiencia BASE | T6: Essalud | U6: =U5*0.09 -> 135 | V6: =V5*0.09 -> 135 | X6: Essalud | Y6: =Y5*0.09 -> 135 | Z6: =Z5*0.09 -> 135 | AB6: Essalud | AC6: =AC5*0.09 -> 135 | AD6: =AD5*0.09 -> 135
C7: Nivel 3 - Maestro cortador | E7: 12 | F7: 0 | I7: =E7*F7 -> 0 | K7: 0.9 | T7: Grati | U7: =U5 -> 1500 | V7: =V5*2 -> 3000 | X7: Grati | Y7: =Y5 -> 1500 | Z7: =Z5*2 -> 3000 | AB7: Grati | AC7: =AC5 -> 1500 | AD7: =AD5*2 -> 3000
A8: AREA DE ENSAMBLADO | I8: =SUM(I5:I7) -> 14 | T8: CTS | U8: 750 | V8: 1500 | X8: CTS | Y8: 750 | Z8: 1500 | AB8: CTS | AC8: 750 | AD8: 1500
C9: Operarios | F9: MAQUINARIA MANUAL | G9: MAQUINARIA SEMIINDUSTRIAL | H9: MAQUINARIA INDUSTRIAL | K9: Total de trabajadores | L9: =SUM(F5:F7,F11:H13,F17:H19) -> 7 | T9: vacaciones | U9: =U5/2 -> 750 | V9: =V5 -> 1500 | X9: vacaciones | Y9: =Y5/2 -> 750 | Z9: =Z5 -> 1500 | AB9: vacaciones | AC9: =AC5/2 -> 750 | AD9: =AD5 -> 1500
F10: 1 | G10: 1.2 | H10: 1.5 | K10: total de trabajadores N3 | L10: =SUM(F7,F13:H13,F19:H19) -> 2 | M10: =L10/L9 -> 0.28571429 | T10: Suma anual | U10: =SUM(U6:U9)+U5*12 -> 21135 | V10: =SUM(V6:V9)+V5*12 -> 24135 | X10: Suma anual | Y10: =SUM(Y6:Y9)+Y5*12 -> 21135 | Z10: =SUM(Z6:Z9)+Z5*12 -> 24135 | AB10: Suma anual | AC10: =SUM(AC6:AC9)+AC5*12 -> 21135 | AD10: =SUM(AD6:AD9)+AD5*12 -> 24135
C11: Nivel 1 | E11: 6 | H11: 1 | I11: =SUM(F11*E11*$F$10,G11*E11*$G$10,H11*E11*$H$10) -> 9 | T11: Pago mensual | U11: =U10/12.5 -> 1690.8 | V11: =V10/13 -> 1856.5385 | X11: Pago mensual | Y11: =Y10/12.5 -> 1690.8 | Z11: =Z10/13 -> 1856.5385 | AB11: Pago mensual | AC11: =AC10/12.5 -> 1690.8 | AD11: =AD10/13 -> 1856.5385
C12: Nivel 2 | E12: 8 | F12: 1 | I12: =SUM(F12*E12*$F$10,G12*E12*$G$10,H12*E12*$H$10) -> 8
C13: Nivel 3 | E13: 12 | G13: 1 | I13: =SUM(F13*E13*$F$10,G13*E13*$G$10,H13*E13*$H$10) -> 14.4 | T13: Cortador con experiencia | U13: MYPE | V13: NoMype | X13: Maquinista industrial | Y13: MYPE | Z13: NoMype | AB13: Técnico de acabado | AC13: MYPE | AD13: NoMype
A14: AREA DE ACABADO | I14: =SUM(I11:I13) -> 31.4 | T14: Sueldo base | U14: 2000 | V14: 2000 | X14: Sueldo base | Y14: 2800 | Z14: 2800 | AB14: Sueldo base | AC14: 2800 | AD14: 2800
C15: Operarios | F15: MAQUINARIA MANUAL | G15: MAQUINARIA SEMIINDUSTRIAL | H15: MAQUINARIA INDUSTRIAL | T15: Essalud | U15: =U14*0.09 -> 180 | V15: =V14*0.09 -> 180 | X15: Essalud | Y15: =Y14*0.09 -> 252 | Z15: =Z14*0.09 -> 252 | AB15: Essalud | AC15: =AC14*0.09 -> 252 | AD15: =AD14*0.09 -> 252
F16: 1 | G16: 1.2 | H16: 1.5 | T16: Grati | U16: =U14 -> 2000 | V16: =V14*2 -> 4000 | X16: Grati | Y16: =Y14 -> 2800 | Z16: =Z14*2 -> 5600 | AB16: Grati | AC16: =AC14 -> 2800 | AD16: =AD14*2 -> 5600
C17: Nivel 1 | E17: 6 | I17: =SUM(F17*E17*$F$16,G17*E17*$G$16,H17*E17*$H$16) -> 0 | T17: CTS | U17: =U14/2 -> 1000 | V17: =V14 -> 2000 | X17: CTS | Y17: 750 | Z17: 1500 | AB17: CTS | AC17: 750 | AD17: 1500
C18: Nivel 2 | E18: 8 | H18: 1 | I18: =SUM(F18*E18*$F$16,G18*E18*$G$16,H18*E18*$H$16) -> 12 | T18: vacaciones | U18: =U14/2 -> 1000 | V18: =V14 -> 2000 | X18: vacaciones | Y18: =Y14/2 -> 1400 | Z18: =Z14 -> 2800 | AB18: vacaciones | AC18: =AC14/2 -> 1400 | AD18: =AD14 -> 2800
C19: Nivel 3 | E19: 12 | F19: 1 | I19: =SUM(F19*E19*$F$16,G19*E19*$G$16,H19*E19*$H$16) -> 12 | T19: Suma anual | U19: =SUM(U15:U18)+U14*12 -> 28180 | V19: =SUM(V15:V18)+V14*12 -> 32180 | X19: Suma anual | Y19: =SUM(Y15:Y18)+Y14*12 -> 38802 | Z19: =SUM(Z15:Z18)+Z14*12 -> 43752 | AB19: Suma anual | AC19: =SUM(AC15:AC18)+AC14*12 -> 38802 | AD19: =SUM(AD15:AD18)+AD14*12 -> 43752
I20: =SUM(I17:I19) -> 24 | T20: Pago mensual | U20: =U19/12.5 -> 2254.4 | V20: =V19/13 -> 2475.3846 | X20: Pago mensual | Y20: =Y19/12.5 -> 3104.16 | Z20: =Z19/13 -> 3365.5385 | AB20: Pago mensual | AC20: =AC19/12.5 -> 3104.16 | AD20: =AD19/13 -> 3365.5385
A21: Jefe de Produccion | F21: 0
T22: Maestro cortador | U22: MYPE | V22: NoMype | X22: Marroquinero especializado | Y22: MYPE | Z22: NoMype | AB22: Artesano acabador | AC22: MYPE | AD22: NoMype
B23: NOTA: EL PROCETANJE DE TRABAJADORES DE NIVEL 3 AFECTA POSITIVAMENTE A LA EFICIENCIA | T23: Sueldo base | U23: 3800 | V23: 3800 | X23: Sueldo base | Y23: 4500 | Z23: 4500 | AB23: Sueldo base | AC23: 4500 | AD23: 4500
T24: Essalud | U24: =U23*0.09 -> 342 | V24: =V23*0.09 -> 342 | X24: Essalud | Y24: =Y23*0.09 -> 405 | Z24: =Z23*0.09 -> 405 | AB24: Essalud | AC24: =AC23*0.09 -> 405 | AD24: =AD23*0.09 -> 405
A25: Calculo de MP | T25: Grati | U25: =U23 -> 3800 | V25: =V23*2 -> 7600 | X25: Grati | Y25: =Y23 -> 4500 | Z25: =Z23*2 -> 9000 | AB25: Grati | AC25: =AC23 -> 4500 | AD25: =AD23*2 -> 9000
T26: CTS | U26: 750 | V26: 1500 | X26: CTS | Y26: 750 | Z26: 1500 | AB26: CTS | AC26: 750 | AD26: 1500
D27: Calidad del cuero | E27: Calidad del cuero | F27: Calidad del cuero | G27: Calidad de accesorios | H27: Calidad de accesorios | I27: Calidad del hilo | J27: Calidad del hilo | K27: Calidad del hilo | T27: vacaciones | U27: =U23/2 -> 1900 | V27: =V23 -> 3800 | X27: vacaciones | Y27: =Y23/2 -> 2250 | Z27: =Z23 -> 4500 | AB27: vacaciones | AC27: =AC23/2 -> 2250 | AD27: =AD23 -> 4500
D28: Nivel 1 - Cuero sintetico | E28: Nivel 2 - Cuero genuino estandar | F28: Nivel 3 - Cuero genuino premium | G28: Nivel 1 - Aleacion economica | H28: Nivel 2 - Metal premium | I28: Nivel 1 - Poliester estandar | J28: Nivel 2 - Encerado reforzado | K28: Nivel 3 - Alta tenacidad (nylon trenzado) | T28: Suma anual | U28: =SUM(U24:U27)+U23*12 -> 52392 | V28: =SUM(V24:V27)+V23*12 -> 58842 | X28: Suma anual | Y28: =SUM(Y24:Y27)+Y23*12 -> 61905 | Z28: =SUM(Z24:Z27)+Z23*12 -> 69405 | AB28: Suma anual | AC28: =SUM(AC24:AC27)+AC23*12 -> 61905 | AD28: =SUM(AD24:AD27)+AD23*12 -> 69405
C29: UM Compra | D29: rollo | E29: Piel completa | F29: Piel completa | G29: Juego | H29: Juego | I29: Carrete | J29: Carrete | K29: Carrete | T29: Pago mensual | U29: =U28/12.5 -> 4191.36 | V29: =V28/13 -> 4526.3077 | X29: Pago mensual | Y29: =Y28/12.5 -> 4952.4 | Z29: =Z28/13 -> 5338.8462 | AB29: Pago mensual | AC29: =AC28/12.5 -> 4952.4 | AD29: =AD28/13 -> 5338.8462
C30: UM Produccion | D30: m2 | E30: m2 | F30: m2 | G30: unidad | H30: unidad | I30: metro | J30: metro | K30: metro
B31: Cantidad necesaria | C31: Compra Jugador | D31: 60 | E31: 55 | F31: 15 | G31: 200 | H31: 190 | I31: 0 | J31: 6 | K31: 7
C32: Cantidad Produccion | D32: 1 | E32: 2 | F32: 2 | G32: 1 | H32: 1 | I32: 270 | J32: 250 | K32: 200 | T32: Jefatura | U32: MYPE | V32: NoMype | X32: Limpieza | Y32: MYPE | Z32: NoMype | AB32: Local de producción | AC32: MYPE | AD32: NoMype
D33: =D31*D32 -> 60 | E33: =E31*E32 -> 110 | F33: =F31*F32 -> 30 | G33: =G31*G32 -> 200 | H33: =H31*H32 -> 190 | I33: =I31*I32 -> 0 | J33: =J31*J32 -> 1500 | K33: =K31*K32 -> 1400 | T33: Sueldo base | U33: 3000 | V33: 3000 | X33: Sueldo base | Y33: 600 | Z33: 600 | AB33: Costo fijo | AC33: 2000 | AD33: 2000
T34: Essalud | U34: =U33*0.09 -> 270 | V34: =V33*0.09 -> 270 | X34: Essalud | Y34: =Y33*0.09 -> 54 | Z34: =Z33*0.09 -> 54
H35: InventarioFinal = InventarioInicial + compras - produccido | T35: Grati | U35: =U33 -> 3000 | V35: =V33*2 -> 6000 | X35: Grati | Y35: =Y33 -> 600 | Z35: =Z33*2 -> 1200
D36: m2 | E36: unidad | F36: metro | H36: Almacen | T36: CTS | U36: 750 | V36: 1500 | X36: CTS | Y36: 750 | Z36: 1500
C37: Moldes (siempre debe comprar al menos uno) | D37: Cuero | E37: Accesorios | F37: Hilos | H37: Cuero | I37: Accesorios | J37: Hilos | T37: vacaciones | U37: =U33/2 -> 1500 | V37: =V33 -> 3000 | X37: vacaciones | Y37: =Y33/2 -> 300 | Z37: =Z33 -> 600
C38: Nivel 1 - Generico basico | D38: 0.3 | E38: 1 | F38: 6 | H38: =SUM(D33:F33) -> 200 | I38: =SUM(G33:H33) -> 390 | J38: =SUM(I33:K33) -> 2900 | T38: Suma anual | U38: =SUM(U34:U37)+U33*12 -> 41520 | V38: =SUM(V34:V37)+V33*12 -> 46770 | X38: Suma anual | Y38: =SUM(Y34:Y37)+Y33*12 -> 8904 | Z38: =SUM(Z34:Z37)+Z33*12 -> 10554
C39: Nivel 2 - Generico mejorado | D39: 0.4 | E39: 1 | F39: 7 | T39: Pago mensual | U39: =U38/12.5 -> 3321.6 | V39: =V38/13 -> 3597.6923 | X39: Pago mensual | Y39: =Y38/12.5 -> 712.32 | Z39: =Z38/13 -> 811.84615
C40: Nivel 3 - Premium | D40: 0.7 | E40: 1 | F40: 13
...

Sheet Lotes_Produccion
A1: Lote | B1: Segmento de venta (elige) | C1: Cantidad de unidades (input) | D1: Codigo Cuero (elige) | E1: Codigo Accesorios (elige) | F1: Codigo Hilo (elige) | G1: Codigo Molde (elige) | H1: Costo unitario insumos (auto) | I1: Puntaje Calidad del lote (auto) | J1: Umbral requerido por segmento (auto) | K1: Resultado (auto) | L1: Mensaje para el jugador (auto)
A2: Lote 1 | B2: SEG-03 | C2: 100 | D2: INS-03 | E2: INS-05 | F2: INS-08 | G2: INF-10 | H2: {=IFERROR(INDEX(Catalogo_Decisiones!$G$2:$G$57,MATCH($D2,Catalogo_Decisiones!$A$2:$A$57,0)),0)+IFERROR(INDEX(Catalogo_Decisiones!$G$2:$G$57,MATCH($E2,Catalogo_Decisiones!$A$2:$A$57,0)),0)+IFERROR(INDEX(Catalogo_Decisiones!$G$2:$G$57,MATCH($F2,Catalogo_Decisiones!$A$2:$A$57,0)),0)} -> 96 | I2: {=IFERROR(INDEX(Catalogo_Decisiones!$H$2:$H$57,MATCH($D2,Catalogo_Decisiones!$A$2:$A$57,0)),0)+IFERROR(INDEX(Catalogo_Decisiones!$H$2:$H$57,MATCH($E2,Catalogo_Decisiones!$A$2:$A$57,0)),0)+IFERROR(INDEX(Catalogo_Decisiones!$H$2:$H$57,MATCH($F2,Catalogo_Decisiones!$A$2:$A$57,0)),0)+IFERROR(INDEX(Catalogo_Decisiones!$H$2:$H$57,MATCH($G2,Catalogo_Decisiones!$A$2:$A$57,0)),0)} -> 12 | J2: =_xlfn.IFS($B2="SEG-01",0,$B2="SEG-02",4,$B2="SEG-03",7,TRUE(),0) -> 7 | K2: =IF(B2="","",IF(I2>=J2,"Coherente","No alcanza el segmento")) -> Coherente | L2: =IF(B2="","Elige un segmento y los insumos del lote",IF(K2="Coherente","Este lote cumple con la calidad esperada para su segmento. Los clientes perciben el valor y el precio se sostiene.","Este lote no alcanza la calidad que su segmento promete. Los clientes se sienten enganados: baja el precio efectivo y la reputacion.")) -> Este lote cumple con la calidad esperada para su segmento. Los clientes perciben el valor y el precio se sostiene.
A3: Lote 2 | B3: SEG-02 | C3: 300 | D3: INS-02 | E3: INS-04 | F3: INS-06 | G3: INF-08 | H3: {=IFERROR(INDEX(Catalogo_Decisiones!$G$2:$G$57,MATCH($D3,Catalogo_Decisiones!$A$2:$A$57,0)),0)+IFERROR(INDEX(Catalogo_Decisiones!$G$2:$G$57,MATCH($E3,Catalogo_Decisiones!$A$2:$A$57,0)),0)+IFERROR(INDEX(Catalogo_Decisiones!$G$2:$G$57,MATCH($F3,Catalogo_Decisiones!$A$2:$A$57,0)),0)} -> 51 | I3: {=IFERROR(INDEX(Catalogo_Decisiones!$H$2:$H$57,MATCH($D3,Catalogo_Decisiones!$A$2:$A$57,0)),0)+IFERROR(INDEX(Catalogo_Decisiones!$H$2:$H$57,MATCH($E3,Catalogo_Decisiones!$A$2:$A$57,0)),0)+IFERROR(INDEX(Catalogo_Decisiones!$H$2:$H$57,MATCH($F3,Catalogo_Decisiones!$A$2:$A$57,0)),0)+IFERROR(INDEX(Catalogo_Decisiones!$H$2:$H$57,MATCH($G3,Catalogo_Decisiones!$A$2:$A$57,0)),0)} -> 5 | J3: =_xlfn.IFS($B3="SEG-01",0,$B3="SEG-02",4,$B3="SEG-03",7,TRUE(),0) -> 4 | K3: =IF(B3="","",IF(I3>=J3,"Coherente","No alcanza el segmento")) -> Coherente | L3: =IF(B3="","Elige un segmento y los insumos del lote",IF(K3="Coherente","Este lote cumple con la calidad esperada para su segmento. Los clientes perciben el valor y el precio se sostiene.","Este lote no alcanza la calidad que su segmento promete. Los clientes se sienten enganados: baja el precio efectivo y la reputacion.")) -> Este lote cumple con la calidad esperada para su segmento. Los clientes perciben el valor y el precio se sostiene.
A4: Lote 3 | B4: SEG-03 | C4: 100 | D4: INS-01 | E4: INS-04 | F4: INS-06 | G4: INF-08 | H4: {=IFERROR(INDEX(Catalogo_Decisiones!$G$2:$G$57,MATCH($D4,Catalogo_Decisiones!$A$2:$A$57,0)),0)+IFERROR(INDEX(Catalogo_Decisiones!$G$2:$G$57,MATCH($E4,Catalogo_Decisiones!$A$2:$A$57,0)),0)+IFERROR(INDEX(Catalogo_Decisiones!$G$2:$G$57,MATCH($F4,Catalogo_Decisiones!$A$2:$A$57,0)),0)} -> 31 | I4: {=IFERROR(INDEX(Catalogo_Decisiones!$H$2:$H$57,MATCH($D4,Catalogo_Decisiones!$A$2:$A$57,0)),0)+IFERROR(INDEX(Catalogo_Decisiones!$H$2:$H$57,MATCH($E4,Catalogo_Decisiones!$A$2:$A$57,0)),0)+IFERROR(INDEX(Catalogo_Decisiones!$H$2:$H$57,MATCH($F4,Catalogo_Decisiones!$A$2:$A$57,0)),0)+IFERROR(INDEX(Catalogo_Decisiones!$H$2:$H$57,MATCH($G4,Catalogo_Decisiones!$A$2:$A$57,0)),0)} -> 4 | J4: =_xlfn.IFS($B4="SEG-01",0,$B4="SEG-02",4,$B4="SEG-03",7,TRUE(),0) -> 7 | K4: =IF(B4="","",IF(I4>=J4,"Coherente","No alcanza el segmento")) -> No alcanza el segmento | L4: =IF(B4="","Elige un segmento y los insumos del lote",IF(K4="Coherente","Este lote cumple con la calidad esperada para su segmento. Los clientes perciben el valor y el precio se sostiene.","Este lote no alcanza la calidad que su segmento promete. Los clientes se sienten enganados: baja el precio efectivo y la reputacion.")) -> Este lote no alcanza la calidad que su segmento promete. Los clientes se sienten enganados: baja el precio efectivo y la reputacion.
A5: TOTAL CICLO | C5: =SUM(C2:C4) -> 500 | H5: =SUMPRODUCT(C2:C4,H2:H4) -> 28000
A7: Nota: cada lote se evalua por separado. El costo unitario de insumos (col H) NO incluye el molde (es inversion fija de Ciclo 0), solo cuero+accesorios+hilo por unidad.

Sheet Motor_Puntajes
A1: Puntaje interno | B1: Valor (suma de aportes) | C1: Escala | D1: Nivel resultante
A2: CALIDAD POR LOTE (detalle)
A3: Puntaje Calidad - Lote 1 | B3: =Lotes_Produccion!I2 -> 12 | C3: =IF(Lotes_Produccion!B2="","","Segmento: "&Lotes_Produccion!B2) -> Segmento: SEG-03 | D3: =Lotes_Produccion!K2 -> Coherente
A4: Puntaje Calidad - Lote 2 | B4: =Lotes_Produccion!I3 -> 5 | C4: =IF(Lotes_Produccion!B3="","","Segmento: "&Lotes_Produccion!B3) -> Segmento: SEG-02 | D4: =Lotes_Produccion!K3 -> Coherente
A5: Puntaje Calidad - Lote 3 | B5: =Lotes_Produccion!I4 -> 4 | C5: =IF(Lotes_Produccion!B4="","","Segmento: "&Lotes_Produccion!B4) -> Segmento: SEG-03 | D5: =Lotes_Produccion!K4 -> No alcanza el segmento
A6: Puntaje Calidad EMPRESA (promedio ponderado por unidades) | B6: =IFERROR(SUMPRODUCT(Lotes_Produccion!C2:C4,Lotes_Produccion!I2:I4)/SUM(Lotes_Produccion!C2:C4),0) -> 6.2 | C6: 0 - 10 (referencial) | D6: =IF(B6>=7,"Alto",IF(B6>=4,"Medio","Bajo")) -> Medio
A8: OTROS PUNTAJES DE EMPRESA
A9: Puntaje de Eficiencia | B9: =SUM(Seleccion_Ciclo0!G2:G15) -> 17 | C9: 0 - 10 (referencial) | D9: =IF(B9>=7,"Alto",IF(B9>=4,"Medio","Bajo")) -> Alto
A10: Puntaje de Reputacion | B10: =SUM(Seleccion_Ciclo0!H2:H15) -> 8 | C10: 0 - 10 (referencial) | D10: =IF(B10>=7,"Alto",IF(B10>=4,"Medio","Bajo")) -> Alto
A11: Puntaje de Salud Financiera | B11: =SUM(Seleccion_Ciclo0!I2:I15) -> -3 | C11: 0 - 10 (referencial) | D11: =IF(B11>=7,"Alto",IF(B11>=4,"Medio","Bajo")) -> Bajo
A13: Nota: cada 'Aporte' se define en la hoja Catalogo_Decisiones (columnas H-K) y se suma automaticamente segun lo elegido en Seleccion_Ciclo0.

Sheet Matriz_Consecuencias
A1: ID | B1: Puntaje evaluado | C1: Condicion | D1: Efecto numerico en el juego | E1: Mensaje textual para el jugador
A2: CONS-01 | B2: Calidad | C2: < 4 y Segmento = Premium | D2: Precio de venta -35%, Reputacion -2 | E2: Posicionaste tu marca como premium, pero tus materiales e insumos no lo respaldan. Los clientes se sienten enganados y las devoluciones aumentan.
A3: CONS-02 | B3: Calidad | C3: >= 7 y Segmento = Premium | D3: Precio de venta +40%, Reputacion +2 | E3: Tu producto cumple con los estandares premium. Los clientes perciben el valor y pagan sin problema el precio elevado.
A4: CONS-03 | B4: Eficiencia | C4: < 4 | D4: Produccion real = 70% de lo planeado (retrasos) | E4: Tu equipo no dio abasto con el volumen que planeaste. Hubo retrasos y entregaste menos de lo prometido.
A5: CONS-04 | B5: Reputacion | C5: < 3 durante 2 ciclos seguidos | D5: Demanda -20% | E5: Tu marca empieza a perder terreno. Los clientes prefieren a la competencia.
A6: CONS-05 | B6: Salud Financiera | C6: < 3 | D6: El banco sube la tasa de interes del proximo prestamo | E6: Tu situacion financiera es riesgosa. El banco te ofrece condiciones menos favorables la proxima vez.
A7: CONS-06 | B7: Produccion vs Capacidad | C7: Cantidad producida > capacidad instalada | D7: Retraso de entrega, costo extra por horas extra | E7: Intentaste producir mas de lo que tu planta soporta. Hubo cuellos de botella y tuviste que pagar horas extra para cumplir.
A8: CONS-07 | B8: Produccion vs Demanda | C8: Cantidad producida > demanda real del mercado | D8: Inventario sin vender, costo de almacenaje | E8: Produjiste mas de lo que el mercado te pidio. Te quedaste con inventario sin vender.
A9: CONS-08 | B9: Eficiencia | C9: Jefatura = No y Eficiencia < 5 | D9: Riesgo de descoordinacion: -5% produccion adicional | E9: Sin jefatura que coordine, tu equipo perdio tiempo resolviendo conflictos de tareas.

Sheet Consecuencias_Oracle
A1: Parámetro | B1: Valor | C1: Regla | D1: Activa | E1: Efecto numérico | F1: Mensaje literal
A2: calidad | B2: 12 | C2: CONS-01 | D2: =AND(B2<4,B3="SEG-03") -> FALSE | E2: =IF(D2,0.65,1) -> 1 | F2: =IF(D2,INDEX(Matriz_Consecuencias!$E$2:$E$9,MATCH(C2,Matriz_Consecuencias!$A$2:$A$9,0)),"")
A3: segmento | B3: SEG-03 | C3: CONS-02 | D3: =AND(B2>=7,B3="SEG-03") -> TRUE | E3: =IF(D3,1.4,1) -> 1.4 | F3: =IF(D3,INDEX(Matriz_Consecuencias!$E$2:$E$9,MATCH(C3,Matriz_Consecuencias!$A$2:$A$9,0)),"") -> Tu producto cumple con los estandares premium. Los clientes perciben el valor y pagan sin problema el precio elevado.
A4: eficiencia | B4: 17 | C4: CONS-03 | D4: =B4<4 -> FALSE | E4: =IF(D4,0.7,1) -> 1 | F4: =IF(D4,INDEX(Matriz_Consecuencias!$E$2:$E$9,MATCH(C4,Matriz_Consecuencias!$A$2:$A$9,0)),"")
A5: reputacion | B5: 8 | C5: CONS-04 | D5: =AND(B5+B15<3,B6+1>=2) -> FALSE | E5: =IF(D5,0.8,1) -> 1 | F5: =IF(D5,INDEX(Matriz_Consecuencias!$E$2:$E$9,MATCH(C5,Matriz_Consecuencias!$A$2:$A$9,0)),"")
A6: ciclosBajaPrevios | B6: 0 | C6: CONS-05 | D6: =B7<3 -> TRUE | E6: =IF(D6,3,0) -> 3 | F6: =IF(D6,INDEX(Matriz_Consecuencias!$E$2:$E$9,MATCH(C6,Matriz_Consecuencias!$A$2:$A$9,0)),"") -> Tu situacion financiera es riesgosa. El banco te ofrece condiciones menos favorables la proxima vez.
A7: saludFinanciera | B7: -3 | C7: CONS-06 | D7: =B9>B10 -> TRUE | E7: =IF(D7,0.25*B13*MIN(1,IFERROR((B9-B10)/B10,0)),0) -> 782.82828 | F7: =IF(D7,INDEX(Matriz_Consecuencias!$E$2:$E$9,MATCH(C7,Matriz_Consecuencias!$A$2:$A$9,0)),"") -> Intentaste producir mas de lo que tu planta soporta. Hubo cuellos de botella y tuviste que pagar horas extra para cumplir.
A8: jefatura | B8: TRUE | C8: CONS-07 | D8: =B11>B12 -> TRUE | E8: =IF(D8,(B11-B12)*2,0) -> 30 | F8: =IF(D8,INDEX(Matriz_Consecuencias!$E$2:$E$9,MATCH(C8,Matriz_Consecuencias!$A$2:$A$9,0)),"") -> Produjiste mas de lo que el mercado te pidio. Te quedaste con inventario sin vender.
A9: planeado | B9: 520 | C9: CONS-08 | D9: =AND(NOT(B8),B4<5) -> FALSE | E9: =IF(D9,0.95,1) -> 1 | F9: =IF(D9,INDEX(Matriz_Consecuencias!$E$2:$E$9,MATCH(C9,Matriz_Consecuencias!$A$2:$A$9,0)),"")
A10: capacidad | B10: 396
A11: producido | B11: 365
A12: demanda | B12: 350
A13: costoMO | B13: 10000
A14: produccionTrasConsecuencias | B14: =ROUNDDOWN(MIN(B9,B10)*E4*E9,0) -> 396
A15: reputacionCambio | B15: =IF(D2,-2,0)+IF(D3,2,0) -> 2
A16: precioFactor | B16: =E2*E3 -> 1.4
A17: ciclosBajaFinal | B17: =IF(B5+B15<3,B6+1,0) -> 0
A19: Extensión autorizada: números de horas extra, almacén y tasa son PENDIENTE_DEFINIR del pedido, no fórmulas originales.

Sheet Mercado_Oracle
A1: empresa | B1: segmento | C1: precio | D1: reputacion | E1: calidad | F1: inventario | G1: factorDemanda | H1: mercadoReal | I1: precioIdeal | J1: pesoPrecio | K1: pesoReputacion | L1: pesoCalidad | M1: puntajePrecio | N1: puntajeTotal | O1: porcentaje | P1: asignado | Q1: vendido | R1: ingreso | S1: inventarioFinal | T1: precioEfectivo
A2: A | B2: SEG-01 | C2: 40 | D2: 7 | E2: 62 | F2: 1000 | G2: 1 | H2: 3500 | I2: 0 | J2: 0.7 | K2: 0.2 | L2: 0.1 | M2: =IF(B2="SEG-01",IFERROR(100*(_xlfn.MAXIFS($C$2:$C$6,$B$2:$B$6,B2)-C2)/(_xlfn.MAXIFS($C$2:$C$6,$B$2:$B$6,B2)-_xlfn.MINIFS($C$2:$C$6,$B$2:$B$6,B2)),100),100-ABS(C2-I2)/I2*100) -> 100 | N2: =J2*M2+K2*D2*10+L2*E2 -> 90.2 | O2: =IFERROR(N2/SUMIF($B$2:$B$6,B2,$N$2:$N$6),0) -> 0.78571429 | P2: =ROUND(O2*H2,0) -> 2750 | Q2: =MIN(P2*G2,F2) -> 1000 | R2: =Q2*T2 -> 40000 | S2: =F2-Q2 -> 0 | T2: =C2 -> 40
A3: B | B3: SEG-01 | C3: 45 | D3: 8.3 | E3: 80 | F3: 1000 | G3: 1 | H3: 3500 | I3: 0 | J3: 0.7 | K3: 0.2 | L3: 0.1 | M3: =IF(B3="SEG-01",IFERROR(100*(_xlfn.MAXIFS($C$2:$C$6,$B$2:$B$6,B3)-C3)/(_xlfn.MAXIFS($C$2:$C$6,$B$2:$B$6,B3)-_xlfn.MINIFS($C$2:$C$6,$B$2:$B$6,B3)),100),100-ABS(C3-I3)/I3*100) -> 0 | N3: =J3*M3+K3*D3*10+L3*E3 -> 24.6 | O3: =IFERROR(N3/SUMIF($B$2:$B$6,B3,$N$2:$N$6),0) -> 0.21428571 | P3: =ROUND(O3*H3,0) -> 750 | Q3: =MIN(P3*G3,F3) -> 750 | R3: =Q3*T3 -> 33750 | S3: =F3-Q3 -> 250 | T3: =C3 -> 45
A4: C | B4: SEG-02 | C4: 120 | D4: 10.2 | E4: 90 | F4: 1000 | G4: 1 | H4: 3500 | I4: 100 | J4: 0.4 | K4: 0.35 | L4: 0.25 | M4: =IF(B4="SEG-01",IFERROR(100*(_xlfn.MAXIFS($C$2:$C$6,$B$2:$B$6,B4)-C4)/(_xlfn.MAXIFS($C$2:$C$6,$B$2:$B$6,B4)-_xlfn.MINIFS($C$2:$C$6,$B$2:$B$6,B4)),100),100-ABS(C4-I4)/I4*100) -> 80 | N4: =J4*M4+K4*D4*10+L4*E4 -> 90.2 | O4: =IFERROR(N4/SUMIF($B$2:$B$6,B4,$N$2:$N$6),0) -> 0.5849546 | P4: =ROUND(O4*H4,0) -> 2047 | Q4: =MIN(P4*G4,F4) -> 1000 | R4: =Q4*T4 -> 120000 | S4: =F4-Q4 -> 0 | T4: =C4 -> 120
A5: D | B5: SEG-02 | C5: 150 | D5: 9 | E5: 50 | F5: 1000 | G5: 1 | H5: 3500 | I5: 100 | J5: 0.4 | K5: 0.35 | L5: 0.25 | M5: =IF(B5="SEG-01",IFERROR(100*(_xlfn.MAXIFS($C$2:$C$6,$B$2:$B$6,B5)-C5)/(_xlfn.MAXIFS($C$2:$C$6,$B$2:$B$6,B5)-_xlfn.MINIFS($C$2:$C$6,$B$2:$B$6,B5)),100),100-ABS(C5-I5)/I5*100) -> 50 | N5: =J5*M5+K5*D5*10+L5*E5 -> 64 | O5: =IFERROR(N5/SUMIF($B$2:$B$6,B5,$N$2:$N$6),0) -> 0.4150454 | P5: =ROUND(O5*H5,0) -> 1453 | Q5: =MIN(P5*G5,F5) -> 1000 | R5: =Q5*T5 -> 150000 | S5: =F5-Q5 -> 0 | T5: =C5 -> 150
A6: E | B6: SEG-03 | C6: 250 | D6: 8 | E6: 100 | F6: 1000 | G6: 1 | H6: 800 | I6: 250 | J6: 0.1 | K6: 0.5 | L6: 0.4 | M6: =IF(B6="SEG-01",IFERROR(100*(_xlfn.MAXIFS($C$2:$C$6,$B$2:$B$6,B6)-C6)/(_xlfn.MAXIFS($C$2:$C$6,$B$2:$B$6,B6)-_xlfn.MINIFS($C$2:$C$6,$B$2:$B$6,B6)),100),100-ABS(C6-I6)/I6*100) -> 100 | N6: =J6*M6+K6*D6*10+L6*E6 -> 90 | O6: =IFERROR(N6/SUMIF($B$2:$B$6,B6,$N$2:$N$6),0) -> 1 | P6: =ROUND(O6*H6,0) -> 800 | Q6: =MIN(P6*G6,F6) -> 800 | R6: =Q6*T6 -> 200000 | S6: =F6-Q6 -> 200 | T6: =C6 -> 250

Sheet SIDE vs Excel
A1: Escenario | B1: Celdas comparadas | C1: OK | D1: Diferencias | E1: Pendientes | F1: Origen esperado
A2: base | B2: 351 | C2: =COUNTIF('Base - 351'!G2:G352,"OK") -> 351 | D2: =COUNTIF('Base - 351'!G2:G352,"DIFERENCIA") -> 0 | E2: =COUNTIF('Base - 351'!G2:G352,"PENDIENTE SIDE") -> 0 | F2: Microsoft Excel COM
A3: sim1_pipeline | B3: 468 | C3: =COUNTIF('SIM1 - Pipeline'!G2:G469,"OK") -> 468 | D3: =COUNTIF('SIM1 - Pipeline'!G2:G469,"DIFERENCIA") -> 0 | E3: =COUNTIF('SIM1 - Pipeline'!G2:G469,"PENDIENTE SIDE") -> 0 | F3: Microsoft Excel COM
A4: sim2_pipeline | B4: 504 | C4: =COUNTIF('SIM2 - Pipeline'!G2:G505,"OK") -> 504 | D4: =COUNTIF('SIM2 - Pipeline'!G2:G505,"DIFERENCIA") -> 0 | E4: =COUNTIF('SIM2 - Pipeline'!G2:G505,"PENDIENTE SIDE") -> 0 | F4: Microsoft Excel COM
A5: sim3_pipeline | B5: 1008 | C5: =COUNTIF('SIM3 - Pipeline'!G2:G1009,"OK") -> 1008 | D5: =COUNTIF('SIM3 - Pipeline'!G2:G1009,"DIFERENCIA") -> 0 | E5: =COUNTIF('SIM3 - Pipeline'!G2:G1009,"PENDIENTE SIDE") -> 0 | F5: Microsoft Excel COM
A6: banca_pipeline | B6: 252 | C6: =COUNTIF('Banca recuperacion'!G2:G253,"OK") -> 252 | D6: =COUNTIF('Banca recuperacion'!G2:G253,"DIFERENCIA") -> 0 | E6: =COUNTIF('Banca recuperacion'!G2:G253,"PENDIENTE SIDE") -> 0 | F6: Microsoft Excel COM
A7: bancamezcla_pipeline | B7: 252 | C7: =COUNTIF('Banca tasas conservadas'!G2:G253,"OK") -> 252 | D7: =COUNTIF('Banca tasas conservadas'!G2:G253,"DIFERENCIA") -> 0 | E7: =COUNTIF('Banca tasas conservadas'!G2:G253,"PENDIENTE SIDE") -> 0 | F7: Microsoft Excel COM
A8: sim2 | B8: 28 | C8: =COUNTIF('CONS baja'!G2:G29,"OK") -> 28 | D8: =COUNTIF('CONS baja'!G2:G29,"DIFERENCIA") -> 0 | E8: =COUNTIF('CONS baja'!G2:G29,"PENDIENTE SIDE") -> 0 | F8: Microsoft Excel COM
A9: sim2_premium | B9: 28 | C9: =COUNTIF('CONS premium'!G2:G29,"OK") -> 28 | D9: =COUNTIF('CONS premium'!G2:G29,"DIFERENCIA") -> 0 | E9: =COUNTIF('CONS premium'!G2:G29,"PENDIENTE SIDE") -> 0 | F9: Microsoft Excel COM
A10: NOTA | B10: Las cuatro divisiones por cero originales de CANTIDAD se conservan y quedan fuera de las comparaciones.
A11: Motor | B11: Microsoft Excel COM 16.0; LibreOffice no instalado.
A12: Independencia | B12: Las hojas de pipeline se construyen exclusivamente desde decisiones y parámetros; los obtenidos SIDE solo llenan las columnas de comparación.

Sheet Base - 351
A1: Clave | B1: Hoja de origen | C1: Celda | D1: Excel recalculado | E1: SIDE obtenido | F1: Diferencia | G1: Estado | H1: SIDE recibido
A2: produccion.I8 | B2: CANTIDAD DE PRODUCCIÓN | C2: I8 | D2: 21 | E2: 21 | F2: =IF(NOT(H2),"",IF(AND(ISNUMBER(D2),ISNUMBER(E2)),E2-D2,IF(D2=E2,0,1))) -> 0 | G2: =IF(NOT(H2),"PENDIENTE SIDE",IF(IF(AND(ISNUMBER(D2),ISNUMBER(E2)),IF(MOD(D2,1)=0,D2=E2,ABS(D2-E2)<=0.000000001*MAX(1,ABS(D2),ABS(E2))),D2=E2),"OK","DIFERENCIA")) -> OK | H2: TRUE
A3: produccion.I14 | B3: CANTIDAD DE PRODUCCIÓN | C3: I14 | D3: 31.4 | E3: 31.4 | F3: =IF(NOT(H3),"",IF(AND(ISNUMBER(D3),ISNUMBER(E3)),E3-D3,IF(D3=E3,0,1))) -> 0 | G3: =IF(NOT(H3),"PENDIENTE SIDE",IF(IF(AND(ISNUMBER(D3),ISNUMBER(E3)),IF(MOD(D3,1)=0,D3=E3,ABS(D3-E3)<=0.000000001*MAX(1,ABS(D3),ABS(E3))),D3=E3),"OK","DIFERENCIA")) -> OK | H3: TRUE
A4: produccion.I20 | B4: CANTIDAD DE PRODUCCIÓN | C4: I20 | D4: 17.2 | E4: 17.2 | F4: =IF(NOT(H4),"",IF(AND(ISNUMBER(D4),ISNUMBER(E4)),E4-D4,IF(D4=E4,0,1))) -> 0 | G4: =IF(NOT(H4),"PENDIENTE SIDE",IF(IF(AND(ISNUMBER(D4),ISNUMBER(E4)),IF(MOD(D4,1)=0,D4=E4,ABS(D4-E4)<=0.000000001*MAX(1,ABS(D4),ABS(E4))),D4=E4),"OK","DIFERENCIA")) -> OK | H4: TRUE
A5: produccion.K5 | B5: CANTIDAD DE PRODUCCIÓN | C5: K5 | D5: 17.2 | E5: 17.2 | F5: =IF(NOT(H5),"",IF(AND(ISNUMBER(D5),ISNUMBER(E5)),E5-D5,IF(D5=E5,0,1))) -> 0 | G5: =IF(NOT(H5),"PENDIENTE SIDE",IF(IF(AND(ISNUMBER(D5),ISNUMBER(E5)),IF(MOD(D5,1)=0,D5=E5,ABS(D5-E5)<=0.000000001*MAX(1,ABS(D5),ABS(E5))),D5=E5),"OK","DIFERENCIA")) -> OK | H5: TRUE
A6: produccion.L5 | B6: CANTIDAD DE PRODUCCIÓN | C6: L5 | D6: 412.8 | E6: 412.8 | F6: =IF(NOT(H6),"",IF(AND(ISNUMBER(D6),ISNUMBER(E6)),E6-D6,IF(D6=E6,0,1))) -> 0 | G6: =IF(NOT(H6),"PENDIENTE SIDE",IF(IF(AND(ISNUMBER(D6),ISNUMBER(E6)),IF(MOD(D6,1)=0,D6=E6,ABS(D6-E6)<=0.000000001*MAX(1,ABS(D6),ABS(E6))),D6=E6),"OK","DIFERENCIA")) -> OK | H6: TRUE
A7: produccion.M5 | B7: CANTIDAD DE PRODUCCIÓN | C7: M5 | D7: 0.96 | E7: 0.96 | F7: =IF(NOT(H7),"",IF(AND(ISNUMBER(D7),ISNUMBER(E7)),E7-D7,IF(D7=E7,0,1))) -> 0 | G7: =IF(NOT(H7),"PENDIENTE SIDE",IF(IF(AND(ISNUMBER(D7),ISNUMBER(E7)),IF(MOD(D7,1)=0,D7=E7,ABS(D7-E7)<=0.000000001*MAX(1,ABS(D7),ABS(E7))),D7=E7),"OK","DIFERENCIA")) -> OK | H7: TRUE
A8: produccion.N5 | B8: CANTIDAD DE PRODUCCIÓN | C8: N5 | D8: 396 | E8: 396 | F8: =IF(NOT(H8),"",IF(AND(ISNUMBER(D8),ISNUMBER(E8)),E8-D8,IF(D8=E8,0,1))) -> 0 | G8: =IF(NOT(H8),"PENDIENTE SIDE",IF(IF(AND(ISNUMBER(D8),ISNUMBER(E8)),IF(MOD(D8,1)=0,D8=E8,ABS(D8-E8)<=0.000000001*MAX(1,ABS(D8),ABS(E8))),D8=E8),"OK","DIFERENCIA")) -> OK | H8: TRUE
A9: produccion.L9 | B9: CANTIDAD DE PRODUCCIÓN | C9: L9 | D9: 8 | E9: 8 | F9: =IF(NOT(H9),"",IF(AND(ISNUMBER(D9),ISNUMBER(E9)),E9-D9,IF(D9=E9,0,1))) -> 0 | G9: =IF(NOT(H9),"PENDIENTE SIDE",IF(IF(AND(ISNUMBER(D9),ISNUMBER(E9)),IF(MOD(D9,1)=0,D9=E9,ABS(D9-E9)<=0.000000001*MAX(1,ABS(D9),ABS(E9))),D9=E9),"OK","DIFERENCIA")) -> OK | H9: TRUE
A10: produccion.L10 | B10: CANTIDAD DE PRODUCCIÓN | C10: L10 | D10: 3 | E10: 3 | F10: =IF(NOT(H10),"",IF(AND(ISNUMBER(D10),ISNUMBER(E10)),E10-D10,IF(D10=E10,0,1))) -> 0 | G10: =IF(NOT(H10),"PENDIENTE SIDE",IF(IF(AND(ISNUMBER(D10),ISNUMBER(E10)),IF(MOD(D10,1)=0,D10=E10,ABS(D10-E10)<=0.000000001*MAX(1,ABS(D10),ABS(E10))),D10=E10),"OK","DIFERENCIA")) -> OK | H10: TRUE
A11: produccion.M10 | B11: CANTIDAD DE PRODUCCIÓN | C11: M10 | D11: 0.375 | E11: 0.375 | F11: =IF(NOT(H11),"",IF(AND(ISNUMBER(D11),ISNUMBER(E11)),E11-D11,IF(D11=E11,0,1))) -> 0 | G11: =IF(NOT(H11),"PENDIENTE SIDE",IF(IF(AND(ISNUMBER(D11),ISNUMBER(E11)),IF(MOD(D11,1)=0,D11=E11,ABS(D11-E11)<=0.000000001*MAX(1,ABS(D11),ABS(E11))),D11=E11),"OK","DIFERENCIA")) -> OK | H11: TRUE
A12: produccion.D37 | B12: CANTIDAD DE PRODUCCIÓN | C12: D37 | D12: 250 | E12: 250 | F12: =IF(NOT(H12),"",IF(AND(ISNUMBER(D12),ISNUMBER(E12)),E12-D12,IF(D12=E12,0,1))) -> 0 | G12: =IF(NOT(H12),"PENDIENTE SIDE",IF(IF(AND(ISNUMBER(D12),ISNUMBER(E12)),IF(MOD(D12,1)=0,D12=E12,ABS(D12-E12)<=0.000000001*MAX(1,ABS(D12),ABS(E12))),D12=E12),"OK","DIFERENCIA")) -> OK | H12: TRUE
A13: produccion.E37 | B13: CANTIDAD DE PRODUCCIÓN | C13: E37 | D13: 190 | E13: 190 | F13: =IF(NOT(H13),"",IF(AND(ISNUMBER(D13),ISNUMBER(E13)),E13-D13,IF(D13=E13,0,1))) -> 0 | G13: =IF(NOT(H13),"PENDIENTE SIDE",IF(IF(AND(ISNUMBER(D13),ISNUMBER(E13)),IF(MOD(D13,1)=0,D13=E13,ABS(D13-E13)<=0.000000001*MAX(1,ABS(D13),ABS(E13))),D13=E13),"OK","DIFERENCIA")) -> OK | H13: TRUE
