Workbook

Sheet Instrucciones
B2: Simulador de empresa de bolsos de cuero — Catalogo maestro de decisiones
B4: Como esta organizado este archivo:
B6: 1) Catalogo_Decisiones: TODAS las opciones posibles del juego. Cada opcion es una fila y cada dato (costo, aporte a cada puntaje) tiene su propia celda — nada esta combinado en una sola celda.
B7: 2) Seleccion_Ciclo0: aqui el jugador elige, por cada grupo de decision (maquinas, personal, canal, etc.), el codigo de la opcion que quiere (lista desplegable en la columna B). Las demas columnas se completan solas con formulas.
B8: 2b) Lotes_Produccion: aqui se decide la calidad POR LOTE, no como promedio de toda la empresa. Cada lote (hasta 3 por ciclo) tiene su propia cantidad de unidades, su propio cuero/accesorios/hilo/molde y su propio segmento de venta. El sistema calcula el Puntaje de Calidad de CADA lote y lo compara contra el segmento elegido (si vendes 'Premium' con insumos bajos, el lote sale 'No alcanza el segmento').
B9: 3) Motor_Puntajes: el Puntaje de Calidad de la empresa es el promedio de los lotes PONDERADO por las unidades de cada uno (un lote de 500 unidades pesa mas que uno de 50). Los otros 3 puntajes (Eficiencia, Reputacion, Salud Financiera) suman los aportes de Seleccion_Ciclo0.
B10: 4) Matriz_Consecuencias: reglas de negocio — que pasa (efecto numerico) y que mensaje ve el jugador segun el valor de cada puntaje.
B12: Celdas amarillas = donde se elige/edita (inputs). Celdas verdes = puntajes/aportes calculados. Celdas grises = fijas u obligatorias.
B14: Para agregar una opcion nueva: agrega una fila en Catalogo_Decisiones con su Codigo unico y sus aportes, y aparecera disponible para elegir en Seleccion_Ciclo0 (agregando el codigo a la lista desplegable del grupo correspondiente).

Sheet DECISIONES
B2: DECISIONES | C2: Puntaje
B3: Depreciación
B4: Garantía del producto
B5: Mantenimiento de maquinaria
B6: Política de inventarios

Sheet Seleccion_Ciclo0
A1: Grupo de decision | B1: Codigo elegido (elige de la lista) | C1: Opcion / Nivel (auto) | D1: Descripcion (auto) | E1: Costo referencial (auto) | F1: Aporte Calidad (auto) | G1: Aporte Eficiencia (auto) | H1: Aporte Reputacion (auto) | I1: Aporte Financiero (auto)
A2: Maquina de ensamblado | C2: =IFERROR(INDEX(Catalogo_Decisiones!$D$2:$D$69,MATCH($B2,Catalogo_Decisiones!$A$2:$A$69,0)),"") | D2: =IFERROR(INDEX(Catalogo_Decisiones!$F$2:$F$69,MATCH($B2,Catalogo_Decisiones!$A$2:$A$69,0)),"") | E2: =IFERROR(INDEX(Catalogo_Decisiones!$G$2:$G$69,MATCH($B2,Catalogo_Decisiones!$A$2:$A$69,0)),0) -> 0 | F2: =IFERROR(INDEX(Catalogo_Decisiones!$H$2:$H$69,MATCH($B2,Catalogo_Decisiones!$A$2:$A$69,0)),0) -> 0 | G2: =IFERROR(INDEX(Catalogo_Decisiones!$I$2:$I$69,MATCH($B2,Catalogo_Decisiones!$A$2:$A$69,0)),0) -> 0 | H2: =IFERROR(INDEX(Catalogo_Decisiones!$J$2:$J$69,MATCH($B2,Catalogo_Decisiones!$A$2:$A$69,0)),0) -> 0 | I2: =IFERROR(INDEX(Catalogo_Decisiones!$K$2:$K$69,MATCH($B2,Catalogo_Decisiones!$A$2:$A$69,0)),0) -> 0
A3: Maquina de acabados | C3: =IFERROR(INDEX(Catalogo_Decisiones!$D$2:$D$69,MATCH($B3,Catalogo_Decisiones!$A$2:$A$69,0)),"") | D3: =IFERROR(INDEX(Catalogo_Decisiones!$F$2:$F$69,MATCH($B3,Catalogo_Decisiones!$A$2:$A$69,0)),"") | E3: =IFERROR(INDEX(Catalogo_Decisiones!$G$2:$G$69,MATCH($B3,Catalogo_Decisiones!$A$2:$A$69,0)),0) -> 0 | F3: =IFERROR(INDEX(Catalogo_Decisiones!$H$2:$H$69,MATCH($B3,Catalogo_Decisiones!$A$2:$A$69,0)),0) -> 0 | G3: =IFERROR(INDEX(Catalogo_Decisiones!$I$2:$I$69,MATCH($B3,Catalogo_Decisiones!$A$2:$A$69,0)),0) -> 0 | H3: =IFERROR(INDEX(Catalogo_Decisiones!$J$2:$J$69,MATCH($B3,Catalogo_Decisiones!$A$2:$A$69,0)),0) -> 0 | I3: =IFERROR(INDEX(Catalogo_Decisiones!$K$2:$K$69,MATCH($B3,Catalogo_Decisiones!$A$2:$A$69,0)),0) -> 0
A4: Molde | C4: =IFERROR(INDEX(Catalogo_Decisiones!$D$2:$D$69,MATCH($B4,Catalogo_Decisiones!$A$2:$A$69,0)),"") | D4: =IFERROR(INDEX(Catalogo_Decisiones!$F$2:$F$69,MATCH($B4,Catalogo_Decisiones!$A$2:$A$69,0)),"") | E4: =IFERROR(INDEX(Catalogo_Decisiones!$G$2:$G$69,MATCH($B4,Catalogo_Decisiones!$A$2:$A$69,0)),0) -> 0 | F4: =IFERROR(INDEX(Catalogo_Decisiones!$H$2:$H$69,MATCH($B4,Catalogo_Decisiones!$A$2:$A$69,0)),0) -> 0 | G4: =IFERROR(INDEX(Catalogo_Decisiones!$I$2:$I$69,MATCH($B4,Catalogo_Decisiones!$A$2:$A$69,0)),0) -> 0 | H4: =IFERROR(INDEX(Catalogo_Decisiones!$J$2:$J$69,MATCH($B4,Catalogo_Decisiones!$A$2:$A$69,0)),0) -> 0 | I4: =IFERROR(INDEX(Catalogo_Decisiones!$K$2:$K$69,MATCH($B4,Catalogo_Decisiones!$A$2:$A$69,0)),0) -> 0
A5: Personal de corte | C5: =IFERROR(INDEX(Catalogo_Decisiones!$D$2:$D$69,MATCH($B5,Catalogo_Decisiones!$A$2:$A$69,0)),"") | D5: =IFERROR(INDEX(Catalogo_Decisiones!$F$2:$F$69,MATCH($B5,Catalogo_Decisiones!$A$2:$A$69,0)),"") | E5: =IFERROR(INDEX(Catalogo_Decisiones!$G$2:$G$69,MATCH($B5,Catalogo_Decisiones!$A$2:$A$69,0)),0) -> 0 | F5: =IFERROR(INDEX(Catalogo_Decisiones!$H$2:$H$69,MATCH($B5,Catalogo_Decisiones!$A$2:$A$69,0)),0) -> 0 | G5: =IFERROR(INDEX(Catalogo_Decisiones!$I$2:$I$69,MATCH($B5,Catalogo_Decisiones!$A$2:$A$69,0)),0) -> 0 | H5: =IFERROR(INDEX(Catalogo_Decisiones!$J$2:$J$69,MATCH($B5,Catalogo_Decisiones!$A$2:$A$69,0)),0) -> 0 | I5: =IFERROR(INDEX(Catalogo_Decisiones!$K$2:$K$69,MATCH($B5,Catalogo_Decisiones!$A$2:$A$69,0)),0) -> 0
A6: Personal de ensamble | C6: =IFERROR(INDEX(Catalogo_Decisiones!$D$2:$D$69,MATCH($B6,Catalogo_Decisiones!$A$2:$A$69,0)),"") | D6: =IFERROR(INDEX(Catalogo_Decisiones!$F$2:$F$69,MATCH($B6,Catalogo_Decisiones!$A$2:$A$69,0)),"") | E6: =IFERROR(INDEX(Catalogo_Decisiones!$G$2:$G$69,MATCH($B6,Catalogo_Decisiones!$A$2:$A$69,0)),0) -> 0 | F6: =IFERROR(INDEX(Catalogo_Decisiones!$H$2:$H$69,MATCH($B6,Catalogo_Decisiones!$A$2:$A$69,0)),0) -> 0 | G6: =IFERROR(INDEX(Catalogo_Decisiones!$I$2:$I$69,MATCH($B6,Catalogo_Decisiones!$A$2:$A$69,0)),0) -> 0 | H6: =IFERROR(INDEX(Catalogo_Decisiones!$J$2:$J$69,MATCH($B6,Catalogo_Decisiones!$A$2:$A$69,0)),0) -> 0 | I6: =IFERROR(INDEX(Catalogo_Decisiones!$K$2:$K$69,MATCH($B6,Catalogo_Decisiones!$A$2:$A$69,0)),0) -> 0
A7: Personal de acabados | C7: =IFERROR(INDEX(Catalogo_Decisiones!$D$2:$D$69,MATCH($B7,Catalogo_Decisiones!$A$2:$A$69,0)),"") | D7: =IFERROR(INDEX(Catalogo_Decisiones!$F$2:$F$69,MATCH($B7,Catalogo_Decisiones!$A$2:$A$69,0)),"") | E7: =IFERROR(INDEX(Catalogo_Decisiones!$G$2:$G$69,MATCH($B7,Catalogo_Decisiones!$A$2:$A$69,0)),0) -> 0 | F7: =IFERROR(INDEX(Catalogo_Decisiones!$H$2:$H$69,MATCH($B7,Catalogo_Decisiones!$A$2:$A$69,0)),0) -> 0 | G7: =IFERROR(INDEX(Catalogo_Decisiones!$I$2:$I$69,MATCH($B7,Catalogo_Decisiones!$A$2:$A$69,0)),0) -> 0 | H7: =IFERROR(INDEX(Catalogo_Decisiones!$J$2:$J$69,MATCH($B7,Catalogo_Decisiones!$A$2:$A$69,0)),0) -> 0 | I7: =IFERROR(INDEX(Catalogo_Decisiones!$K$2:$K$69,MATCH($B7,Catalogo_Decisiones!$A$2:$A$69,0)),0) -> 0
A8: Jefatura | C8: =IFERROR(INDEX(Catalogo_Decisiones!$D$2:$D$69,MATCH($B8,Catalogo_Decisiones!$A$2:$A$69,0)),"") | D8: =IFERROR(INDEX(Catalogo_Decisiones!$F$2:$F$69,MATCH($B8,Catalogo_Decisiones!$A$2:$A$69,0)),"") | E8: =IFERROR(INDEX(Catalogo_Decisiones!$G$2:$G$69,MATCH($B8,Catalogo_Decisiones!$A$2:$A$69,0)),0) -> 0 | F8: =IFERROR(INDEX(Catalogo_Decisiones!$H$2:$H$69,MATCH($B8,Catalogo_Decisiones!$A$2:$A$69,0)),0) -> 0 | G8: =IFERROR(INDEX(Catalogo_Decisiones!$I$2:$I$69,MATCH($B8,Catalogo_Decisiones!$A$2:$A$69,0)),0) -> 0 | H8: =IFERROR(INDEX(Catalogo_Decisiones!$J$2:$J$69,MATCH($B8,Catalogo_Decisiones!$A$2:$A$69,0)),0) -> 0 | I8: =IFERROR(INDEX(Catalogo_Decisiones!$K$2:$K$69,MATCH($B8,Catalogo_Decisiones!$A$2:$A$69,0)),0) -> 0
A9: Canal de venta | C9: =IFERROR(INDEX(Catalogo_Decisiones!$D$2:$D$69,MATCH($B9,Catalogo_Decisiones!$A$2:$A$69,0)),"") | D9: =IFERROR(INDEX(Catalogo_Decisiones!$F$2:$F$69,MATCH($B9,Catalogo_Decisiones!$A$2:$A$69,0)),"") | E9: =IFERROR(INDEX(Catalogo_Decisiones!$G$2:$G$69,MATCH($B9,Catalogo_Decisiones!$A$2:$A$69,0)),0) -> 0 | F9: =IFERROR(INDEX(Catalogo_Decisiones!$H$2:$H$69,MATCH($B9,Catalogo_Decisiones!$A$2:$A$69,0)),0) -> 0 | G9: =IFERROR(INDEX(Catalogo_Decisiones!$I$2:$I$69,MATCH($B9,Catalogo_Decisiones!$A$2:$A$69,0)),0) -> 0 | H9: =IFERROR(INDEX(Catalogo_Decisiones!$J$2:$J$69,MATCH($B9,Catalogo_Decisiones!$A$2:$A$69,0)),0) -> 0 | I9: =IFERROR(INDEX(Catalogo_Decisiones!$K$2:$K$69,MATCH($B9,Catalogo_Decisiones!$A$2:$A$69,0)),0) -> 0
A10: Acceso a prestamo bancario | C10: =IFERROR(INDEX(Catalogo_Decisiones!$D$2:$D$69,MATCH($B10,Catalogo_Decisiones!$A$2:$A$69,0)),"") | D10: =IFERROR(INDEX(Catalogo_Decisiones!$F$2:$F$69,MATCH($B10,Catalogo_Decisiones!$A$2:$A$69,0)),"") | E10: =IFERROR(INDEX(Catalogo_Decisiones!$G$2:$G$69,MATCH($B10,Catalogo_Decisiones!$A$2:$A$69,0)),0) -> 0 | F10: =IFERROR(INDEX(Catalogo_Decisiones!$H$2:$H$69,MATCH($B10,Catalogo_Decisiones!$A$2:$A$69,0)),0) -> 0 | G10: =IFERROR(INDEX(Catalogo_Decisiones!$I$2:$I$69,MATCH($B10,Catalogo_Decisiones!$A$2:$A$69,0)),0) -> 0 | H10: =IFERROR(INDEX(Catalogo_Decisiones!$J$2:$J$69,MATCH($B10,Catalogo_Decisiones!$A$2:$A$69,0)),0) -> 0 | I10: =IFERROR(INDEX(Catalogo_Decisiones!$K$2:$K$69,MATCH($B10,Catalogo_Decisiones!$A$2:$A$69,0)),0) -> 0
A11: Numero de proveedores | C11: =IFERROR(INDEX(Catalogo_Decisiones!$D$2:$D$69,MATCH($B11,Catalogo_Decisiones!$A$2:$A$69,0)),"") | D11: =IFERROR(INDEX(Catalogo_Decisiones!$F$2:$F$69,MATCH($B11,Catalogo_Decisiones!$A$2:$A$69,0)),"") | E11: =IFERROR(INDEX(Catalogo_Decisiones!$G$2:$G$69,MATCH($B11,Catalogo_Decisiones!$A$2:$A$69,0)),0) -> 0 | F11: =IFERROR(INDEX(Catalogo_Decisiones!$H$2:$H$69,MATCH($B11,Catalogo_Decisiones!$A$2:$A$69,0)),0) -> 0 | G11: =IFERROR(INDEX(Catalogo_Decisiones!$I$2:$I$69,MATCH($B11,Catalogo_Decisiones!$A$2:$A$69,0)),0) -> 0 | H11: =IFERROR(INDEX(Catalogo_Decisiones!$J$2:$J$69,MATCH($B11,Catalogo_Decisiones!$A$2:$A$69,0)),0) -> 0 | I11: =IFERROR(INDEX(Catalogo_Decisiones!$K$2:$K$69,MATCH($B11,Catalogo_Decisiones!$A$2:$A$69,0)),0) -> 0
A12: Politica de pago a proveedores | C12: =IFERROR(INDEX(Catalogo_Decisiones!$D$2:$D$69,MATCH($B12,Catalogo_Decisiones!$A$2:$A$69,0)),"") | D12: =IFERROR(INDEX(Catalogo_Decisiones!$F$2:$F$69,MATCH($B12,Catalogo_Decisiones!$A$2:$A$69,0)),"") | E12: =IFERROR(INDEX(Catalogo_Decisiones!$G$2:$G$69,MATCH($B12,Catalogo_Decisiones!$A$2:$A$69,0)),0) -> 0 | F12: =IFERROR(INDEX(Catalogo_Decisiones!$H$2:$H$69,MATCH($B12,Catalogo_Decisiones!$A$2:$A$69,0)),0) -> 0 | G12: =IFERROR(INDEX(Catalogo_Decisiones!$I$2:$I$69,MATCH($B12,Catalogo_Decisiones!$A$2:$A$69,0)),0) -> 0 | H12: =IFERROR(INDEX(Catalogo_Decisiones!$J$2:$J$69,MATCH($B12,Catalogo_Decisiones!$A$2:$A$69,0)),0) -> 0 | I12: =IFERROR(INDEX(Catalogo_Decisiones!$K$2:$K$69,MATCH($B12,Catalogo_Decisiones!$A$2:$A$69,0)),0) -> 0
A13: Lead time | C13: =IFERROR(INDEX(Catalogo_Decisiones!$D$2:$D$69,MATCH($B13,Catalogo_Decisiones!$A$2:$A$69,0)),"") | D13: =IFERROR(INDEX(Catalogo_Decisiones!$F$2:$F$69,MATCH($B13,Catalogo_Decisiones!$A$2:$A$69,0)),"") | E13: =IFERROR(INDEX(Catalogo_Decisiones!$G$2:$G$69,MATCH($B13,Catalogo_Decisiones!$A$2:$A$69,0)),0) -> 0 | F13: =IFERROR(INDEX(Catalogo_Decisiones!$H$2:$H$69,MATCH($B13,Catalogo_Decisiones!$A$2:$A$69,0)),0) -> 0 | G13: =IFERROR(INDEX(Catalogo_Decisiones!$I$2:$I$69,MATCH($B13,Catalogo_Decisiones!$A$2:$A$69,0)),0) -> 0 | H13: =IFERROR(INDEX(Catalogo_Decisiones!$J$2:$J$69,MATCH($B13,Catalogo_Decisiones!$A$2:$A$69,0)),0) -> 0 | I13: =IFERROR(INDEX(Catalogo_Decisiones!$K$2:$K$69,MATCH($B13,Catalogo_Decisiones!$A$2:$A$69,0)),0) -> 0
... A15: Inversion en marketing | C15: =IFERROR(INDEX(Catalogo_Decisiones!$D$2:$D$69,MATCH($B15,Catalogo_Decisiones!$A$2:$A$69,0)),"") | D15: =IFERROR(INDEX(Catalogo_Decisiones!$F$2:$F$69,MATCH($B15,Catalogo_Decisiones!$A$2:$A$69,0)),"") | E15: =IFERROR(INDEX(Catalogo_Decisiones!$G$2:$G$69,MATCH($B15,Catalogo_Decisiones!$A$2:$A$69,0)),0) -> 0 | F15: =IFERROR(INDEX(Catalogo_Decisiones!$H$2:$H$69,MATCH($B15,Catalogo_Decisiones!$A$2:$A$69,0)),0) -> 0 | G15: =IFERROR(INDEX(Catalogo_Decisiones!$I$2:$I$69,MATCH($B15,Catalogo_Decisiones!$A$2:$A$69,0)),0) -> 0 | H15: =IFERROR(INDEX(Catalogo_Decisiones!$J$2:$J$69,MATCH($B15,Catalogo_Decisiones!$A$2:$A$69,0)),0) -> 0 | I15: =IFERROR(INDEX(Catalogo_Decisiones!$K$2:$K$69,MATCH($B15,Catalogo_Decisiones!$A$2:$A$69,0)),0) -> 0
A16: --- Otras decisiones numericas ---
A17: PRO-01 - Cantidad inicial a producir (unidades) | B17: 0
A18: COM-02 - N° de tiendas en zona alta (Miraflores) | B18: 0
A19: COM-03 - N° de tiendas en zona media (Los Olivos / San Miguel) | B19: 0
A20: COM-04 - N° de tiendas en zona baja (SJL / SMP) | B20: 0
A21: COM-05N - % de ventas a credito (0-100) | B21: 0
A22: FIN-01M - Monto de prestamo solicitado (S/) | B22: 0
A24: Método de depreciación | C24: =IFERROR(INDEX(Catalogo_Decisiones!$D$2:$D$69,MATCH($B24,Catalogo_Decisiones!$A$2:$A$69,0)),"") | D24: =IFERROR(INDEX(Catalogo_Decisiones!$F$2:$F$69,MATCH($B24,Catalogo_Decisiones!$A$2:$A$69,0)),"") | E24: =IFERROR(INDEX(Catalogo_Decisiones!$G$2:$G$69,MATCH($B24,Catalogo_Decisiones!$A$2:$A$69,0)),0) -> 0 | F24: =IFERROR(INDEX(Catalogo_Decisiones!$H$2:$H$69,MATCH($B24,Catalogo_Decisiones!$A$2:$A$69,0)),0) -> 0 | G24: =IFERROR(INDEX(Catalogo_Decisiones!$I$2:$I$69,MATCH($B24,Catalogo_Decisiones!$A$2:$A$69,0)),0) -> 0 | H24: =IFERROR(INDEX(Catalogo_Decisiones!$J$2:$J$69,MATCH($B24,Catalogo_Decisiones!$A$2:$A$69,0)),0) -> 0 | I24: =IFERROR(INDEX(Catalogo_Decisiones!$K$2:$K$69,MATCH($B24,Catalogo_Decisiones!$A$2:$A$69,0)),0) -> 0
A25: Garantía | C25: =IFERROR(INDEX(Catalogo_Decisiones!$D$2:$D$69,MATCH($B25,Catalogo_Decisiones!$A$2:$A$69,0)),"") | D25: =IFERROR(INDEX(Catalogo_Decisiones!$F$2:$F$69,MATCH($B25,Catalogo_Decisiones!$A$2:$A$69,0)),"") | E25: =IFERROR(INDEX(Catalogo_Decisiones!$G$2:$G$69,MATCH($B25,Catalogo_Decisiones!$A$2:$A$69,0)),0) -> 0 | F25: =IFERROR(INDEX(Catalogo_Decisiones!$H$2:$H$69,MATCH($B25,Catalogo_Decisiones!$A$2:$A$69,0)),0) -> 0 | G25: =IFERROR(INDEX(Catalogo_Decisiones!$I$2:$I$69,MATCH($B25,Catalogo_Decisiones!$A$2:$A$69,0)),0) -> 0 | H25: =IFERROR(INDEX(Catalogo_Decisiones!$J$2:$J$69,MATCH($B25,Catalogo_Decisiones!$A$2:$A$69,0)),0) -> 0 | I25: =IFERROR(INDEX(Catalogo_Decisiones!$K$2:$K$69,MATCH($B25,Catalogo_Decisiones!$A$2:$A$69,0)),0) -> 0
A26: Mantenimiento | C26: =IFERROR(INDEX(Catalogo_Decisiones!$D$2:$D$69,MATCH($B26,Catalogo_Decisiones!$A$2:$A$69,0)),"") | D26: =IFERROR(INDEX(Catalogo_Decisiones!$F$2:$F$69,MATCH($B26,Catalogo_Decisiones!$A$2:$A$69,0)),"") | E26: =IFERROR(INDEX(Catalogo_Decisiones!$G$2:$G$69,MATCH($B26,Catalogo_Decisiones!$A$2:$A$69,0)),0) -> 0 | F26: =IFERROR(INDEX(Catalogo_Decisiones!$H$2:$H$69,MATCH($B26,Catalogo_Decisiones!$A$2:$A$69,0)),0) -> 0 | G26: =IFERROR(INDEX(Catalogo_Decisiones!$I$2:$I$69,MATCH($B26,Catalogo_Decisiones!$A$2:$A$69,0)),0) -> 0 | H26: =IFERROR(INDEX(Catalogo_Decisiones!$J$2:$J$69,MATCH($B26,Catalogo_Decisiones!$A$2:$A$69,0)),0) -> 0 | I26: =IFERROR(INDEX(Catalogo_Decisiones!$K$2:$K$69,MATCH($B26,Catalogo_Decisiones!$A$2:$A$69,0)),0) -> 0
A27: Política de inventarios | C27: =IFERROR(INDEX(Catalogo_Decisiones!$D$2:$D$69,MATCH($B27,Catalogo_Decisiones!$A$2:$A$69,0)),"") | D27: =IFERROR(INDEX(Catalogo_Decisiones!$F$2:$F$69,MATCH($B27,Catalogo_Decisiones!$A$2:$A$69,0)),"") | E27: =IFERROR(INDEX(Catalogo_Decisiones!$G$2:$G$69,MATCH($B27,Catalogo_Decisiones!$A$2:$A$69,0)),0) -> 0 | F27: =IFERROR(INDEX(Catalogo_Decisiones!$H$2:$H$69,MATCH($B27,Catalogo_Decisiones!$A$2:$A$69,0)),0) -> 0 | G27: =IFERROR(INDEX(Catalogo_Decisiones!$I$2:$I$69,MATCH($B27,Catalogo_Decisiones!$A$2:$A$69,0)),0) -> 0 | H27: =IFERROR(INDEX(Catalogo_Decisiones!$J$2:$J$69,MATCH($B27,Catalogo_Decisiones!$A$2:$A$69,0)),0) -> 0 | I27: =IFERROR(INDEX(Catalogo_Decisiones!$K$2:$K$69,MATCH($B27,Catalogo_Decisiones!$A$2:$A$69,0)),0) -> 0

Sheet Catalogo_Decisiones
A1: Codigo | B1: Bloque | C1: Grupo de decision | D1: Opcion / Nivel | E1: Permanencia | F1: Descripcion | G1: Costo referencial (S/) | H1: Aporte Calidad | I1: Aporte Eficiencia | J1: Aporte Reputacion | K1: Aporte Financiero | L1: Notas
A2: GEN-01 | B2: A. Empresa | C2: Razon social | D2: Texto libre | E2: Fija | F2: Nombre legal de la empresa (texto) | G2: 0 | H2: 0 | I2: 0 | J2: 0 | K2: 0 | L2: Sin efecto en puntajes
A3: GEN-02 | B3: A. Empresa | C3: Nombre comercial / marca | D3: Texto libre | E3: Fija | F3: Marca comercial (texto) | G3: 0 | H3: 0 | I3: 0 | J3: 0 | K3: 0 | L3: Sin efecto en puntajes
A4: GEN-04 | B4: A. Empresa | C4: Tipos de bolsos | D4: Texto libre | E4: Fija | F4: Linea de productos que fabrica (tote, cartera, mochila, etc.) | G4: 0 | H4: 0 | I4: 0 | J4: 0 | K4: 0 | L4: Sin efecto en puntajes
A5: SEG-01 | B5: A. Empresa | C5: Segmento / linea | D5: Economico | E5: Fija | F5: Precio bajo, prioriza volumen y costo | G5: 0 | H5: 0 | I5: 0 | J5: 1 | K5: 0 | L5: Exige coherencia con Calidad real
A6: SEG-02 | B6: A. Empresa | C6: Segmento / linea | D6: Estandar | E6: Fija | F6: Equilibra costo, calidad, demanda y margen | G6: 0 | H6: 1 | I6: 0 | J6: 1 | K6: 0
A7: SEG-03 | B7: A. Empresa | C7: Segmento / linea | D7: Premium | E7: Fija | F7: Precio alto; requiere Calidad>=7 para sostenerse | G7: 0 | H7: 2 | I7: 0 | J7: 2 | K7: 0 | L7: Riesgo si Calidad interna es baja (ver Matriz)
A8: INF-01 | B8: B. Infraestructura | C8: Mesa de corte | D8: Unica (obligatoria) | E8: Fija | F8: Inversion fija para todos; habilita la etapa de corte | G8: 2500 | H8: 0 | I8: 1 | J8: 0 | K8: 0 | L8: Obligatoria, no otorga niveles
A9: INF-02 | B9: B. Infraestructura | C9: Maquina de ensamblado | D9: Nivel 1: manual/basica | E9: Fija | F9: Costura Singer 4423 Heavy Duty; desbastadora a mano con cuchilla o lija | G9: 3500 | H9: 1 | I9: 1 | J9: 0 | K9: 0
A10: INF-03 | B10: B. Infraestructura | C10: Maquina de ensamblado | D10: Nivel 2: semi-industrial | E10: Fija | F10: Maquina de coser de columna/brazo (poste) Typical TB-801 | G10: 7500 | H10: 2 | I10: 2 | J10: 0 | K10: 0
A11: INF-04 | B11: B. Infraestructura | C11: Maquina de ensamblado | D11: Nivel 3: industrial | E11: Fija | F11: Juki de triple accionamiento; desbastadora automatica de alta precision, servomotor | G11: 15000 | H11: 3 | I11: 3 | J11: 0 | K11: 0
A12: INF-05 | B12: B. Infraestructura | C12: Maquina de acabados | D12: Nivel 1: manual/basica | E12: Fija | F12: Acabado a mano con cera/tinte de bordes, bruñido manual. Lento, variable en calidad | G12: 1200 | H12: 1 | I12: 1 | J12: 0 | K12: 0
A13: INF-06 | B13: B. Infraestructura | C13: Maquina de acabados | D13: Nivel 2: semi-industrial | E13: Fija | F13: Maquina de pulido de bordes (edge burnisher) electrica, tinte con pincel/aerografo | G13: 4500 | H13: 2 | I13: 2 | J13: 0 | K13: 0
A14: INF-07 | B14: B. Infraestructura | C14: Maquina de acabados | D14: Nivel 3: industrial | E14: Fija | F14: Linea de acabado con teñido automatico + pulido, control de temperatura y velocidad | G14: 9500 | H14: 3 | I14: 3 | J14: 0 | K14: 0
A15: INF-08 | B15: B. Infraestructura | C15: Molde | D15: Nivel 1 - Generico basico | E15: Fija | F15: Patrones simples, tipo plantilla estandar de internet o catalogo generico | G15: 300 | H15: 1 | I15: 1 | J15: 0 | K15: 0 | L15: Bajo aprovechamiento de cuero
A16: INF-09 | B16: B. Infraestructura | C16: Molde | D16: Nivel 2 - Generico mejorado | E16: Fija | F16: Patron tecnico mas elaborado, con lineas de corte, marcado y perforaciones bien definidas | G16: 1200 | H16: 2 | I16: 2 | J16: 1 | K16: 0 | L16: Aprovechamiento medio-alto
A17: INF-10 | B17: B. Infraestructura | C17: Molde | D17: Nivel 3 - Premium | E17: Fija | F17: La empresa desarrolla su propio patron desde cero, adaptado a su propuesta de marca | G17: 3500 | H17: 4 | I17: 2 | J17: 2 | K17: 0 | L17: Maximo aprovechamiento y diferenciacion
A18: RH-01 | B18: C. RRHH | C18: Personal de corte | D18: Nivel 1 - Operario basico | E18: Revisable con costo | F18: Corta con plantilla simple, sin experiencia previa. Mas lento, mas margen de error | G18: 1500 | H18: 0 | I18: 1 | J18: 0 | K18: 0
A19: RH-02 | B19: C. RRHH | C19: Personal de corte | D19: Nivel 2 - Cortador con experiencia | E19: Revisable con costo | F19: Optimiza el aprovechamiento del cuero, reduce desperdicio, mas rapido | G19: 2500 | H19: 1 | I19: 2 | J19: 0 | K19: 0
A20: RH-03 | B20: C. RRHH | C20: Personal de corte | D20: Nivel 3 - Maestro cortador | E20: Revisable con costo | F20: Trabaja cueros irregulares/premium, maximo aprovechamiento, minimo desperdicio | G20: 4000 | H20: 2 | I20: 3 | J20: 0 | K20: 0
A21: RH-04 | B21: C. RRHH | C21: Personal de ensamble | D21: Nivel 1 - Costurero basico | E21: Revisable con costo | F21: Maquina domestica, puntadas rectas simples, funciona con diseños sencillos | G21: 1500 | H21: 0 | I21: 1 | J21: 0 | K21: 0
A22: RH-05 | B22: C. RRHH | C22: Personal de ensamble | D22: Nivel 2 - Maquinista industrial | E22: Revisable con costo | F22: Maquina semi-industrial/industrial, costuras reforzadas, mayor velocidad | G22: 2800 | H22: 1 | I22: 2 | J22: 0 | K22: 0
A23: RH-06 | B23: C. RRHH | C23: Personal de ensamble | D23: Nivel 3 - Marroquinero especializado | E23: Revisable con costo | F23: Costura a mano de alta gama, ejecuta moldes exclusivos complejos, ideal linea premium | G23: 4500 | H23: 2 | I23: 3 | J23: 1 | K23: 0
A24: RH-07 | B24: C. RRHH | C24: Personal de acabados | D24: Nivel 1 - Operario de acabado basico | E24: Revisable con costo | F24: Aplica tinte y cera de forma simple, resultado variable | G24: 1500 | H24: 0 | I24: 1 | J24: 0 | K24: 0
A25: RH-08 | B25: C. RRHH | C25: Personal de acabados | D25: Nivel 2 - Tecnico en acabados | E25: Revisable con costo | F25: Maneja maquina de pulido de bordes, tinte con aerografo, resultado consistente | G25: 2800 | H25: 1 | I25: 2 | J25: 0 | K25: 0
A26: RH-09 | B26: C. RRHH | C26: Personal de acabados | D26: Nivel 3 - Artesano acabador | E26: Revisable con costo | F26: Bruñido fino, dorado, decoracion compleja (pedreria, herrajes especiales) | G26: 4500 | H26: 2 | I26: 3 | J26: 1 | K26: 0
A27: RH-10A | B27: C. RRHH | C27: Jefatura | D27: Contratar jefatura | E27: Revisable con costo | F27: Coordina el equipo, reduce riesgo de descoordinacion | G27: 3000 | H27: 0 | I27: 2 | J27: 1 | K27: 0
A28: RH-10B | B28: C. RRHH | C28: Jefatura | D28: No contratar jefatura | E28: Revisable con costo | F28: Ahorra costo fijo, pero aumenta el riesgo de descoordinacion | G28: 0 | H28: 0 | I28: -1 | J28: 0 | K28: 1 | L28: Ahorro de caja pero baja Eficiencia
A29: RH-11 | B29: C. RRHH | C29: Limpieza y servicios generales | D29: Unica (obligatoria) | E29: Fija | F29: Monto fijo obligatorio para mantener la operacion | G29: 600 | H29: 0 | I29: 0 | J29: 0 | K29: 0
A30: RH-12 | B30: C. RRHH | C30: Local de produccion | D30: Estandar (unico) | E30: Fija | F30: Local de produccion estandar; alquiler fijo igual para todos los equipos | G30: 2000 | H30: 0 | I30: 0 | J30: 0 | K30: 0
A31: COM-01A | B31: D. Canales | C31: Canal de venta | D31: Solo tienda fisica | E31: Revisable cada ciclo | F31: Menor cobertura y demanda; menor complejidad y costo | G31: 0 | H31: 0 | I31: 0 | J31: 0 | K31: 1
A32: COM-01B | B32: D. Canales | C32: Canal de venta | D32: Solo web | E32: Revisable cada ciclo | F32: Cobertura amplia con menor costo fijo; depende de marketing digital | G32: 500 | H32: 0 | I32: 0 | J32: 1 | K32: 0
A33: COM-01C | B33: D. Canales | C33: Canal de venta | D33: Web y fisico | E33: Revisable cada ciclo | F33: Mayor cobertura y demanda; incrementa complejidad y costo | G33: 1500 | H33: 0 | I33: 0 | J33: 2 | K33: -1
A34: FIN-01A | B34: D. Canales | C34: Acceso a prestamo bancario | D34: Solicitar prestamo | E34: Fija: habilita | F34: Habilita apalancamiento; permite invertir mas rapido | G34: 0 | H34: 0 | I34: 0 | J34: 0 | K34: -1 | L34: Aumenta apalancamiento
A35: FIN-01B | B35: D. Canales | C35: Acceso a prestamo bancario | D35: No solicitar prestamo | E35: Fija: habilita | F35: Evita intereses; la expansion depende del capital propio | G35: 0 | H35: 0 | I35: 0 | J35: 1 | K35: 1
A36: INS-01 | B36: E. Insumos | C36: Calidad del cuero | D36: Nivel 1 - Cuero sintetico | E36: Revisable cada ciclo | F36: Bajo costo, menor durabilidad, acabado menos premium | G36: 25 | H36: 1 | I36: 0 | J36: 0 | K36: 1 | L36: por unidad, referencial
A37: INS-02 | B37: E. Insumos | C37: Calidad del cuero | D37: Nivel 2 - Cuero genuino estandar | E37: Revisable cada ciclo | F37: Costo medio, durabilidad media | G37: 45 | H37: 2 | I37: 0 | J37: 0 | K37: 0 | L37: por unidad, referencial
A38: INS-03 | B38: E. Insumos | C38: Calidad del cuero | D38: Nivel 3 - Cuero genuino premium | E38: Revisable cada ciclo | F38: Full grain / curtido vegetal: alto costo, alta durabilidad, mejor acabado | G38: 80 | H38: 3 | I38: 0 | J38: 1 | K38: -1 | L38: por unidad, referencial
A39: INS-04 | B39: E. Insumos | C39: Calidad de accesorios | D39: Nivel 1 - Aleacion economica | E39: Revisable cada ciclo | F39: Bajo costo, se oxida/desgasta mas rapido | G39: 4 | H39: 1 | I39: 0 | J39: 0 | K39: 1 | L39: por unidad, referencial
A40: INS-05 | B40: E. Insumos | C40: Calidad de accesorios | D40: Nivel 2 - Metal premium | E40: Revisable cada ciclo | F40: Laton macizo o acero inoxidable, alto costo, mayor durabilidad y brillo | G40: 9 | H40: 2 | I40: 0 | J40: 1 | K40: -1 | L40: por unidad, referencial
...

Sheet FlujoWeb
B3: Flujo
B4: Steps | C4: Docente | D4: Jugadores | H4: Valeria y Gonzalo
B5: 1 | C5: Launcher | H5: Erick y Miguel
B6: 2 | C6: Login | E6: Se valida el codigo de sala y el nombre empresa(usuario)
B7: 3 | C7: Configuracion del juego (incluye Creacion de Sala)
B8: 4 | D8: Launcher
B9: 5 | D9: Login
B10: 6 | D10: Tutorial | E10: Indicaciones en un carrusel.
A11: Ciclo 1 | B11: 7 | D11: Decisiones
B12: 8 | D12: Espera (Fin de ciclo) | E12: El docente define si se hace automatico o manual
B13: 9 | C13: Información en vivo de las decisiones de los jugadores (Manual: Cierra el ciclo)
B14: 10 | C14: Estados financieros Generales | D14: Estados financieros Individuales e Informacion del mercado | E14: Descargables en pdf
A15: Ciclo 2 | B15: 11 | D15: Decisiones
B16: 12 | D16: Espera (Fin de ciclo)
B17: 13 | C17: Información en vivo de las decisiones de los jugadores (Manual: Cierra el ciclo)
B18: 14 | C18: Estados financieros Generales | D18: Estados financieros Individuales e Informacion del mercado | E18: Descargables en pdf
A19: Ciclo 3 | B19: 15 | D19: Decisiones
B20: 16 | D20: Espera (Fin de ciclo)
B21: 17 | C21: Información en vivo de las decisiones de los jugadores (Manual: Cierra el ciclo)
B22: 18 | C22: Estados financieros Generales | D22: Estados financieros Individuales e Informacion del mercado | E22: Descargables en pdf
A23: Ciclo N | B23: 15 | D23: Decisiones
B24: 16 | D24: Espera (Fin de ciclo)
B25: 17 | C25: Información en vivo de las decisiones de los jugadores (Manual: Cierra el ciclo)
B26: 18 | C26: Estados financieros Generales | D26: Estados financieros Individuales e Informacion del mercado
B27: 23 | C27: Resumen General - Indicar podio | D27: Estados financieros Individuales y Consolidado Final | E27: Descargables en pdf
B28: 24 | D28: Mostrar Podio | E28: Agregar disclaimer indicando que los datos se guardaran un maximo de 24 horas
B37: Si el jugador no tomo decision dentro del tiempo establecido y es la primera decisión se le elimina del juego
B38: El Docente tiene la opcion de eliminar jugadores en cualquier momento. Sin importar si es manual o automatico
B39: Si el jugador no tomo decisiones dentro del tiempo establecido y no es la primera decisión el sistema replica las decisiones del ciclo anterior.

Sheet CANTIDAD DE PRODUCCIÓN
A1: Calculo de MO
A3: AREA DE CORTE
E4: Bolsas por día | F4: Mesa de corte | K4: Producción por día | L4: AL MES | M4: Eficiencia | N4: Produccion Real
C5: Nivel 1 - Operario basico | E5: 5 | F5: 1 | I5: =E5*F5 -> 5 | K5: =MIN(I8,I14,I20) -> 17.2 | L5: =K5*24 -> 412.8 | M5: =MIN(1,K7+SUM(F7,F13:H13,F19:H19)/100+4%*F21) -> 0.97 | N5: =ROUND(L5*M5,0) -> 400 | O5: Esta produccion no puede ser superior a lo que permite el material
C6: Nivel 2 - Cortador con experiencia | E6: 7 | F6: 1 | I6: =E6*F6 -> 7 | K6: Eficiencia BASE
C7: Nivel 3 - Maestro cortador | E7: 9 | F7: 1 | I7: =E7*F7 -> 9 | K7: 0.9
A8: AREA DE ENSAMBLADO | I8: =SUM(I5:I7) -> 21
C9: Operarios | F9: MAQUINARIA MANUAL | G9: MAQUINARIA SEMIINDUSTRIAL | H9: MAQUINARIA INDUSTRIAL | K9: Total de trabajadores | L9: =SUM(F5:F7,F11:H13,F17:H19) -> 8
F10: 1 | G10: 1.2 | H10: 1.5 | K10: total de trabajadores N3 | L10: =SUM(F7,F13:H13,F19:H19) -> 3 | M10: =IFERROR(L10/L9,0) -> 0.375
C11: Nivel 1 | E11: 6 | H11: 1 | I11: =SUM(F11*E11*$F$10,G11*E11*$G$10,H11*E11*$H$10) -> 9
C12: Nivel 2 | E12: 8 | F12: 1 | G12: 0 | I12: =SUM(F12*E12*$F$10,G12*E12*$G$10,H12*E12*$H$10) -> 8
C13: Nivel 3 | E13: 12 | G13: 1 | I13: =SUM(F13*E13*$F$10,G13*E13*$G$10,H13*E13*$H$10) -> 14.4
A14: AREA DE ACABADO | I14: =SUM(I11:I13) -> 31.4
C15: Operarios | F15: MAQUINARIA MANUAL | G15: MAQUINARIA SEMIINDUSTRIAL | H15: MAQUINARIA INDUSTRIAL
F16: 1 | G16: 1.2 | H16: 1.5
C17: Nivel 1 | E17: 6 | G17: 1 | I17: =SUM(F17*E17*$F$16,G17*E17*$G$16,H17*E17*$H$16) -> 7.2
C18: Nivel 2 | E18: 7 | G18: 0 | H18: 0 | I18: =SUM(F18*E18*$F$16,G18*E18*$G$16,H18*E18*$H$16) -> 0
C19: Nivel 3 | E19: 10 | F19: 1 | I19: =SUM(F19*E19*$F$16,G19*E19*$G$16,H19*E19*$H$16) -> 10
I20: =SUM(I17:I19) -> 17.2
A21: Jefe de Produccion | F21: 1
B23: NOTA: EL PROCETANJE DE TRABAJADORES DE NIVEL 3 AFECTA POSITIVAMENTE A LA EFICIENCIA
A25: Calculo de MP
D27: Calidad del cuero | E27: Calidad del cuero | F27: Calidad del cuero | G27: Calidad de accesorios | H27: Calidad de accesorios | I27: Calidad de accesorios | J27: Calidad del hilo | K27: Calidad del hilo | L27: Calidad del hilo
D28: Nivel 1 - Cuero sintetico | E28: Nivel 2 - Cuero genuino estandar | F28: Nivel 3 - Cuero genuino premium | G28: Nivel 1 - Aleacion economica | H28: Nivel 2 - Metal premium | I28: Nivel 3 - Metal Deluxe | J28: Nivel 1 - Poliester estandar | K28: Nivel 2 - Encerado reforzado | L28: Nivel 3 - Alta tenacidad (nylon trenzado)
C29: UM Compra | D29: rollo | E29: Piel completa | F29: Piel completa | G29: Juego | H29: Juego | I29: Juego | J29: Carrete | K29: Carrete | L29: Carrete
C30: UM Produccion | D30: m2 | E30: m2 | F30: m2 | G30: unidad | H30: unidad | I30: unidad | J30: metro | K30: metro | L30: metro
C31: Nivel 1 - Generico basico | D31: 0.3 | G31: 1 | J31: 6
C32: Nivel 2 - Generico mejorado | E32: 0.4 | H32: 1 | K32: 7
C33: Nivel 3 - Premium | F33: 0.7 | I33: 1 | L33: 13
E35: =N5 -> 400
C36: Cantidad que desea producir | D36: =SUM(D37:D39) -> 520 | E36: =SUM(E37:E39) -> 399
C37: Nivel 1 - Generico basico | D37: 250 | E37: =IFERROR(ROUNDDOWN(D37*E35/D36,0),0) -> 192
C38: Nivel 2 - Generico mejorado | D38: 180 | E38: =IFERROR(ROUNDDOWN(D38*E35/D36,0),0) -> 138
C39: Nivel 3 - Premium | D39: 90 | E39: =IFERROR(ROUNDDOWN(D39*E35/D36,0),0) -> 69
D40: Calidad del cuero | E40: Calidad del cuero | F40: Calidad del cuero | G40: Calidad de accesorios | H40: Calidad de accesorios | I40: Calidad de accesorios | J40: Calidad del hilo | K40: Calidad del hilo | L40: Calidad del hilo
D41: Nivel 1 - Cuero sintetico | E41: Nivel 2 - Cuero genuino estandar | F41: Nivel 3 - Cuero genuino premium | G41: Nivel 1 - Aleacion economica | H41: Nivel 2 - Metal premium | I41: Nivel 3 - Metal Deluxe | J41: Nivel 1 - Poliester estandar | K41: Nivel 2 - Encerado reforzado | L41: Nivel 3 - Alta tenacidad (nylon trenzado)
C42: Nivel 1 - Generico basico | D42: =$D37*D31 -> 75 | E42: =$D37*E31 -> 0 | F42: =$D37*F31 -> 0 | G42: =$D37*G31 -> 250 | H42: =$D37*H31 -> 0 | I42: =$D37*I31 -> 0 | J42: =$D37*J31 -> 1500 | K42: =$D37*K31 -> 0 | L42: =$D37*L31 -> 0
C43: Nivel 2 - Generico mejorado | D43: =$D38*D32 -> 0 | E43: =$D38*E32 -> 72 | F43: =$D38*F32 -> 0 | G43: =$D38*G32 -> 0 | H43: =$D38*H32 -> 180 | I43: =$D38*I32 -> 0 | J43: =$D38*J32 -> 0 | K43: =$D38*K32 -> 1260 | L43: =$D38*L32 -> 0
C44: Nivel 3 - Premium | D44: =$D39*D33 -> 0 | E44: =$D39*E33 -> 0 | F44: =$D39*F33 -> 63 | G44: =$D39*G33 -> 0 | H44: =$D39*H33 -> 0 | I44: =$D39*I33 -> 90 | J44: =$D39*J33 -> 0 | K44: =$D39*K33 -> 0 | L44: =$D39*L33 -> 1170
D47: Calidad del cuero | E47: Calidad del cuero | F47: Calidad del cuero | G47: Calidad de accesorios | H47: Calidad de accesorios | I47: Calidad de accesorios | J47: Calidad del hilo | K47: Calidad del hilo | L47: Calidad del hilo
...

Sheet Costos De Producción
A1: Calculo de MO
T2: Costos: MO
A3: AREA DE CORTE
E4: Bolsas por día | F4: Mesa de corte | K4: Producción por día | L4: AL MES | M4: Eficiencia | N4: Produccion Real | T4: O.Basico | U4: MYPE | V4: NoMype | X4: Costurero básico | Y4: MYPE | Z4: NoMype | AB4: Operario de acabado clásico | AC4: MYPE | AD4: NoMype
C5: Nivel 1 - Operario basico | E5: ='CANTIDAD DE PRODUCCIÓN'!E5 -> 5 | F5: 1 | I5: =E5*F5 -> 5 | K5: =MIN(I8,I14,I20) -> 12 | L5: =K5*24 -> 288 | M5: =MIN(1,K7+SUM(F7,F13:H13,F19:H19)/100+4%*F21) -> 0.92 | N5: =ROUND(L5*M5,0) -> 265 | O5: Esta produccion no puede ser superior a lo que permite el material | T5: Sueldo base | U5: 1500 | V5: 1500 | X5: Sueldo base | Y5: 1500 | Z5: 1500 | AB5: Sueldo base | AC5: 1500 | AD5: 1500
C6: Nivel 2 - Cortador con experiencia | E6: ='CANTIDAD DE PRODUCCIÓN'!E6 -> 7 | F6: 1 | I6: =E6*F6 -> 7 | K6: Eficiencia BASE | T6: Essalud | U6: =U5*0.09 -> 135 | V6: =V5*0.09 -> 135 | X6: Essalud | Y6: =Y5*0.09 -> 135 | Z6: =Z5*0.09 -> 135 | AB6: Essalud | AC6: =AC5*0.09 -> 135 | AD6: =AD5*0.09 -> 135
C7: Nivel 3 - Maestro cortador | E7: ='CANTIDAD DE PRODUCCIÓN'!E7 -> 9 | F7: 0 | I7: =E7*F7 -> 0 | K7: 0.9 | T7: Grati | U7: =U5 -> 1500 | V7: =V5*2 -> 3000 | X7: Grati | Y7: =Y5 -> 1500 | Z7: =Z5*2 -> 3000 | AB7: Grati | AC7: =AC5 -> 1500 | AD7: =AD5*2 -> 3000
A8: AREA DE ENSAMBLADO | I8: =SUM(I5:I7) -> 12 | T8: CTS | U8: 750 | V8: 1500 | X8: CTS | Y8: 750 | Z8: 1500 | AB8: CTS | AC8: 750 | AD8: 1500
C9: Operarios | F9: MAQUINARIA MANUAL | G9: MAQUINARIA SEMIINDUSTRIAL | H9: MAQUINARIA INDUSTRIAL | K9: Total de trabajadores | L9: =SUM(F5:F7,F11:H13,F17:H19) -> 7 | T9: vacaciones | U9: =U5/2 -> 750 | V9: =V5 -> 1500 | X9: vacaciones | Y9: =Y5/2 -> 750 | Z9: =Z5 -> 1500 | AB9: vacaciones | AC9: =AC5/2 -> 750 | AD9: =AD5 -> 1500
F10: 1 | G10: 1.2 | H10: 1.5 | K10: total de trabajadores N3 | L10: =SUM(F7,F13:H13,F19:H19) -> 2 | M10: =IFERROR(L10/L9,0) -> 0.28571429 | T10: Suma anual | U10: =SUM(U6:U9)+U5*12 -> 21135 | V10: =SUM(V6:V9)+V5*12 -> 24135 | X10: Suma anual | Y10: =SUM(Y6:Y9)+Y5*12 -> 21135 | Z10: =SUM(Z6:Z9)+Z5*12 -> 24135 | AB10: Suma anual | AC10: =SUM(AC6:AC9)+AC5*12 -> 21135 | AD10: =SUM(AD6:AD9)+AD5*12 -> 24135
C11: Nivel 1 | E11: ='CANTIDAD DE PRODUCCIÓN'!E11 -> 6 | H11: 1 | I11: =SUM(F11*E11*$F$10,G11*E11*$G$10,H11*E11*$H$10) -> 9 | T11: Pago mensual | U11: =U10/12.5 -> 1690.8 | V11: =V10/13 -> 1856.5385 | X11: Pago mensual | Y11: =Y10/12.5 -> 1690.8 | Z11: =Z10/13 -> 1856.5385 | AB11: Pago mensual | AC11: =AC10/12.5 -> 1690.8 | AD11: =AD10/13 -> 1856.5385
C12: Nivel 2 | E12: ='CANTIDAD DE PRODUCCIÓN'!E12 -> 8 | F12: 1 | I12: =SUM(F12*E12*$F$10,G12*E12*$G$10,H12*E12*$H$10) -> 8
C13: Nivel 3 | E13: ='CANTIDAD DE PRODUCCIÓN'!E13 -> 12 | G13: 1 | I13: =SUM(F13*E13*$F$10,G13*E13*$G$10,H13*E13*$H$10) -> 14.4 | T13: Cortador con experiencia | U13: MYPE | V13: NoMype | X13: Maquinista industrial | Y13: MYPE | Z13: NoMype | AB13: Técnico de acabado | AC13: MYPE | AD13: NoMype
A14: AREA DE ACABADO | I14: =SUM(I11:I13) -> 31.4 | T14: Sueldo base | U14: 2000 | V14: 2000 | X14: Sueldo base | Y14: 2800 | Z14: 2800 | AB14: Sueldo base | AC14: 2800 | AD14: 2800
C15: Operarios | F15: MAQUINARIA MANUAL | G15: MAQUINARIA SEMIINDUSTRIAL | H15: MAQUINARIA INDUSTRIAL | T15: Essalud | U15: =U14*0.09 -> 180 | V15: =V14*0.09 -> 180 | X15: Essalud | Y15: =Y14*0.09 -> 252 | Z15: =Z14*0.09 -> 252 | AB15: Essalud | AC15: =AC14*0.09 -> 252 | AD15: =AD14*0.09 -> 252
F16: 1 | G16: 1.2 | H16: 1.5 | T16: Grati | U16: =U14 -> 2000 | V16: =V14*2 -> 4000 | X16: Grati | Y16: =Y14 -> 2800 | Z16: =Z14*2 -> 5600 | AB16: Grati | AC16: =AC14 -> 2800 | AD16: =AD14*2 -> 5600
C17: Nivel 1 | E17: ='CANTIDAD DE PRODUCCIÓN'!E17 -> 6 | I17: =SUM(F17*E17*$F$16,G17*E17*$G$16,H17*E17*$H$16) -> 0 | T17: CTS | U17: =U14/2 -> 1000 | V17: =V14 -> 2000 | X17: CTS | Y17: 750 | Z17: 1500 | AB17: CTS | AC17: 750 | AD17: 1500
C18: Nivel 2 | E18: ='CANTIDAD DE PRODUCCIÓN'!E18 -> 7 | H18: 1 | I18: =SUM(F18*E18*$F$16,G18*E18*$G$16,H18*E18*$H$16) -> 10.5 | T18: vacaciones | U18: =U14/2 -> 1000 | V18: =V14 -> 2000 | X18: vacaciones | Y18: =Y14/2 -> 1400 | Z18: =Z14 -> 2800 | AB18: vacaciones | AC18: =AC14/2 -> 1400 | AD18: =AD14 -> 2800
C19: Nivel 3 | E19: ='CANTIDAD DE PRODUCCIÓN'!E19 -> 10 | F19: 1 | I19: =SUM(F19*E19*$F$16,G19*E19*$G$16,H19*E19*$H$16) -> 10 | T19: Suma anual | U19: =SUM(U15:U18)+U14*12 -> 28180 | V19: =SUM(V15:V18)+V14*12 -> 32180 | X19: Suma anual | Y19: =SUM(Y15:Y18)+Y14*12 -> 38802 | Z19: =SUM(Z15:Z18)+Z14*12 -> 43752 | AB19: Suma anual | AC19: =SUM(AC15:AC18)+AC14*12 -> 38802 | AD19: =SUM(AD15:AD18)+AD14*12 -> 43752
I20: =SUM(I17:I19) -> 20.5 | T20: Pago mensual | U20: =U19/12.5 -> 2254.4 | V20: =V19/13 -> 2475.3846 | X20: Pago mensual | Y20: =Y19/12.5 -> 3104.16 | Z20: =Z19/13 -> 3365.5385 | AB20: Pago mensual | AC20: =AC19/12.5 -> 3104.16 | AD20: =AD19/13 -> 3365.5385
A21: Jefe de Produccion | F21: 0
T22: Maestro cortador | U22: MYPE | V22: NoMype | X22: Marroquinero especializado | Y22: MYPE | Z22: NoMype | AB22: Artesano acabador | AC22: MYPE | AD22: NoMype
B23: NOTA: EL PROCETANJE DE TRABAJADORES DE NIVEL 3 AFECTA POSITIVAMENTE A LA EFICIENCIA | T23: Sueldo base | U23: 3800 | V23: 3800 | X23: Sueldo base | Y23: 4500 | Z23: 4500 | AB23: Sueldo base | AC23: 4500 | AD23: 4500
T24: Essalud | U24: =U23*0.09 -> 342 | V24: =V23*0.09 -> 342 | X24: Essalud | Y24: =Y23*0.09 -> 405 | Z24: =Z23*0.09 -> 405 | AB24: Essalud | AC24: =AC23*0.09 -> 405 | AD24: =AD23*0.09 -> 405
A25: Calculo de MP | T25: Grati | U25: =U23 -> 3800 | V25: =V23*2 -> 7600 | X25: Grati | Y25: =Y23 -> 4500 | Z25: =Z23*2 -> 9000 | AB25: Grati | AC25: =AC23 -> 4500 | AD25: =AD23*2 -> 9000
T26: CTS | U26: 750 | V26: 1500 | X26: CTS | Y26: 750 | Z26: 1500 | AB26: CTS | AC26: 750 | AD26: 1500
D27: Calidad del cuero | E27: Calidad del cuero | F27: Calidad del cuero | G27: Calidad de accesorios | H27: Calidad de accesorios | I27: Calidad del hilo | J27: Calidad del hilo | K27: Calidad del hilo | T27: vacaciones | U27: =U23/2 -> 1900 | V27: =V23 -> 3800 | X27: vacaciones | Y27: =Y23/2 -> 2250 | Z27: =Z23 -> 4500 | AB27: vacaciones | AC27: =AC23/2 -> 2250 | AD27: =AD23 -> 4500
D28: Nivel 1 - Cuero sintetico | E28: Nivel 2 - Cuero genuino estandar | F28: Nivel 3 - Cuero genuino premium | G28: Nivel 1 - Aleacion economica | H28: Nivel 2 - Metal premium | I28: Nivel 1 - Poliester estandar | J28: Nivel 2 - Encerado reforzado | K28: Nivel 3 - Alta tenacidad (nylon trenzado) | T28: Suma anual | U28: =SUM(U24:U27)+U23*12 -> 52392 | V28: =SUM(V24:V27)+V23*12 -> 58842 | X28: Suma anual | Y28: =SUM(Y24:Y27)+Y23*12 -> 61905 | Z28: =SUM(Z24:Z27)+Z23*12 -> 69405 | AB28: Suma anual | AC28: =SUM(AC24:AC27)+AC23*12 -> 61905 | AD28: =SUM(AD24:AD27)+AD23*12 -> 69405
C29: UM Compra | D29: rollo | E29: Piel completa | F29: Piel completa | G29: Juego | H29: Juego | I29: Carrete | J29: Carrete | K29: Carrete | T29: Pago mensual | U29: =U28/12.5 -> 4191.36 | V29: =V28/13 -> 4526.3077 | X29: Pago mensual | Y29: =Y28/12.5 -> 4952.4 | Z29: =Z28/13 -> 5338.8462 | AB29: Pago mensual | AC29: =AC28/12.5 -> 4952.4 | AD29: =AD28/13 -> 5338.8462
C30: UM Produccion | D30: m2 | E30: m2 | F30: m2 | G30: unidad | H30: unidad | I30: metro | J30: metro | K30: metro
B31: Cantidad necesaria | C31: Compra Jugador | D31: 60 | E31: 55 | F31: 15 | G31: 200 | H31: 190 | I31: 0 | J31: 6 | K31: 7
C32: Cantidad Produccion | D32: 1 | E32: 2 | F32: 2 | G32: 1 | H32: 1 | I32: 270 | J32: 250 | K32: 200 | T32: Jefatura | U32: MYPE | V32: NoMype | X32: Limpieza | Y32: MYPE | Z32: NoMype | AB32: Local de producción | AC32: MYPE | AD32: NoMype
D33: =D31*D32 -> 60 | E33: =E31*E32 -> 110 | F33: =F31*F32 -> 30 | G33: =G31*G32 -> 200 | H33: =H31*H32 -> 190 | I33: =I31*I32 -> 0 | J33: =J31*J32 -> 1500 | K33: =K31*K32 -> 1400 | T33: Sueldo base | U33: 3000 | V33: 3000 | X33: Sueldo base | Y33: 600 | Z33: 600 | AB33: Costo fijo | AC33: 2000 | AD33: 2000
T34: Essalud | U34: =U33*0.09 -> 270 | V34: =V33*0.09 -> 270 | X34: Essalud | Y34: =Y33*0.09 -> 54 | Z34: =Z33*0.09 -> 54
H35: InventarioFinal = InventarioInicial + compras - produccido | T35: Grati | U35: =U33 -> 3000 | V35: =V33*2 -> 6000 | X35: Grati | Y35: =Y33 -> 600 | Z35: =Z33*2 -> 1200
D36: m2 | E36: unidad | F36: metro | H36: Almacen | T36: CTS | U36: 750 | V36: 1500 | X36: CTS | Y36: 750 | Z36: 1500
C37: Moldes (siempre debe comprar al menos uno) | D37: Cuero | E37: Accesorios | F37: Hilos | H37: Cuero | I37: Accesorios | J37: Hilos | T37: vacaciones | U37: =U33/2 -> 1500 | V37: =V33 -> 3000 | X37: vacaciones | Y37: =Y33/2 -> 300 | Z37: =Z33 -> 600
C38: Nivel 1 - Generico basico | D38: 0.3 | E38: 1 | F38: 6 | H38: =SUM(D33:F33) -> 200 | I38: =SUM(G33:H33) -> 390 | J38: =SUM(I33:K33) -> 2900 | T38: Suma anual | U38: =SUM(U34:U37)+U33*12 -> 41520 | V38: =SUM(V34:V37)+V33*12 -> 46770 | X38: Suma anual | Y38: =SUM(Y34:Y37)+Y33*12 -> 8904 | Z38: =SUM(Z34:Z37)+Z33*12 -> 10554
C39: Nivel 2 - Generico mejorado | D39: 0.4 | E39: 1 | F39: 7 | T39: Pago mensual | U39: =U38/12.5 -> 3321.6 | V39: =V38/13 -> 3597.6923 | X39: Pago mensual | Y39: =Y38/12.5 -> 712.32 | Z39: =Z38/13 -> 811.84615
C40: Nivel 3 - Premium | D40: 0.7 | E40: 1 | F40: 13
...

Sheet Lotes_Produccion
A1: Lote | B1: Segmento de venta (elige) | C1: Cantidad de unidades (input) | D1: Codigo Cuero (elige) | E1: Codigo Accesorios (elige) | F1: Codigo Hilo (elige) | G1: Codigo Molde (elige) | H1: Costo unitario insumos (auto) | I1: Puntaje Calidad del lote (auto) | J1: Umbral requerido por segmento (auto) | K1: Resultado (auto) | L1: Mensaje para el jugador (auto) | M1: Precio elegido (S/ por unidad) | N1: Validación de precio | O1: Precio efectivo tras consecuencias
A2: Lote 1 | C2: 0 | H2: =IFERROR(INDEX(Catalogo_Decisiones!$G$2:$G$69,MATCH($D2,Catalogo_Decisiones!$A$2:$A$69,0)),0)+IFERROR(INDEX(Catalogo_Decisiones!$G$2:$G$69,MATCH($E2,Catalogo_Decisiones!$A$2:$A$69,0)),0)+IFERROR(INDEX(Catalogo_Decisiones!$G$2:$G$69,MATCH($F2,Catalogo_Decisiones!$A$2:$A$69,0)),0) -> 0 | I2: =MAX(0,MIN(10,IFERROR(INDEX(Catalogo_Decisiones!$H$2:$H$69,MATCH($D2,Catalogo_Decisiones!$A$2:$A$69,0)),0)+IFERROR(INDEX(Catalogo_Decisiones!$H$2:$H$69,MATCH($E2,Catalogo_Decisiones!$A$2:$A$69,0)),0)+IFERROR(INDEX(Catalogo_Decisiones!$H$2:$H$69,MATCH($F2,Catalogo_Decisiones!$A$2:$A$69,0)),0)+IFERROR(INDEX(Catalogo_Decisiones!$H$2:$H$69,MATCH($G2,Catalogo_Decisiones!$A$2:$A$69,0)),0))) -> 0 | J2: =IF(B2="SEG-03",7,IF(B2="SEG-02",4,0)) -> 0 | K2: =IF(B2="","",IF(I2>=J2,"Coherente","No alcanza el segmento")) | L2: =IF(B2="","Elige un segmento y los insumos del lote",IF(K2="Coherente","Este lote cumple con la calidad esperada para su segmento. Los clientes perciben el valor y el precio se sostiene.","Este lote no alcanza la calidad que su segmento promete. Los clientes se sienten enganados: baja el precio efectivo y la reputacion.")) -> Elige un segmento y los insumos del lote | M2: 42.5 | N2: =IF(B2="","",IF(AND(M2>=IF(B2="SEG-01",40,IF(B2="SEG-02",120,220)),M2<=IF(B2="SEG-01",45,IF(B2="SEG-02",200,400))),"Válido","Fuera de rango")) | O2: =M2*IF(B2="SEG-03",IF(I2<7,0.65,1.4),1) -> 42.5
A3: Lote 2 | C3: 0 | H3: =IFERROR(INDEX(Catalogo_Decisiones!$G$2:$G$69,MATCH($D3,Catalogo_Decisiones!$A$2:$A$69,0)),0)+IFERROR(INDEX(Catalogo_Decisiones!$G$2:$G$69,MATCH($E3,Catalogo_Decisiones!$A$2:$A$69,0)),0)+IFERROR(INDEX(Catalogo_Decisiones!$G$2:$G$69,MATCH($F3,Catalogo_Decisiones!$A$2:$A$69,0)),0) -> 0 | I3: =MAX(0,MIN(10,IFERROR(INDEX(Catalogo_Decisiones!$H$2:$H$69,MATCH($D3,Catalogo_Decisiones!$A$2:$A$69,0)),0)+IFERROR(INDEX(Catalogo_Decisiones!$H$2:$H$69,MATCH($E3,Catalogo_Decisiones!$A$2:$A$69,0)),0)+IFERROR(INDEX(Catalogo_Decisiones!$H$2:$H$69,MATCH($F3,Catalogo_Decisiones!$A$2:$A$69,0)),0)+IFERROR(INDEX(Catalogo_Decisiones!$H$2:$H$69,MATCH($G3,Catalogo_Decisiones!$A$2:$A$69,0)),0))) -> 0 | J3: =IF(B3="SEG-03",7,IF(B3="SEG-02",4,0)) -> 0 | K3: =IF(B3="","",IF(I3>=J3,"Coherente","No alcanza el segmento")) | L3: =IF(B3="","Elige un segmento y los insumos del lote",IF(K3="Coherente","Este lote cumple con la calidad esperada para su segmento. Los clientes perciben el valor y el precio se sostiene.","Este lote no alcanza la calidad que su segmento promete. Los clientes se sienten enganados: baja el precio efectivo y la reputacion.")) -> Elige un segmento y los insumos del lote | M3: 160 | N3: =IF(B3="","",IF(AND(M3>=IF(B3="SEG-01",40,IF(B3="SEG-02",120,220)),M3<=IF(B3="SEG-01",45,IF(B3="SEG-02",200,400))),"Válido","Fuera de rango")) | O3: =M3*IF(B3="SEG-03",IF(I3<7,0.65,1.4),1) -> 160
A4: Lote 3 | C4: 0 | H4: =IFERROR(INDEX(Catalogo_Decisiones!$G$2:$G$69,MATCH($D4,Catalogo_Decisiones!$A$2:$A$69,0)),0)+IFERROR(INDEX(Catalogo_Decisiones!$G$2:$G$69,MATCH($E4,Catalogo_Decisiones!$A$2:$A$69,0)),0)+IFERROR(INDEX(Catalogo_Decisiones!$G$2:$G$69,MATCH($F4,Catalogo_Decisiones!$A$2:$A$69,0)),0) -> 0 | I4: =MAX(0,MIN(10,IFERROR(INDEX(Catalogo_Decisiones!$H$2:$H$69,MATCH($D4,Catalogo_Decisiones!$A$2:$A$69,0)),0)+IFERROR(INDEX(Catalogo_Decisiones!$H$2:$H$69,MATCH($E4,Catalogo_Decisiones!$A$2:$A$69,0)),0)+IFERROR(INDEX(Catalogo_Decisiones!$H$2:$H$69,MATCH($F4,Catalogo_Decisiones!$A$2:$A$69,0)),0)+IFERROR(INDEX(Catalogo_Decisiones!$H$2:$H$69,MATCH($G4,Catalogo_Decisiones!$A$2:$A$69,0)),0))) -> 0 | J4: =IF(B4="SEG-03",7,IF(B4="SEG-02",4,0)) -> 0 | K4: =IF(B4="","",IF(I4>=J4,"Coherente","No alcanza el segmento")) | L4: =IF(B4="","Elige un segmento y los insumos del lote",IF(K4="Coherente","Este lote cumple con la calidad esperada para su segmento. Los clientes perciben el valor y el precio se sostiene.","Este lote no alcanza la calidad que su segmento promete. Los clientes se sienten enganados: baja el precio efectivo y la reputacion.")) -> Elige un segmento y los insumos del lote | M4: 250 | N4: =IF(B4="","",IF(AND(M4>=IF(B4="SEG-01",40,IF(B4="SEG-02",120,220)),M4<=IF(B4="SEG-01",45,IF(B4="SEG-02",200,400))),"Válido","Fuera de rango")) | O4: =M4*IF(B4="SEG-03",IF(I4<7,0.65,1.4),1) -> 250
A5: TOTAL CICLO | C5: =SUM(C2:C4) -> 0 | H5: =SUMPRODUCT(C2:C4,H2:H4) -> 0
A7: Nota: cada lote se evalua por separado. El costo unitario de insumos (col H) NO incluye el molde (es inversion fija de Ciclo 0), solo cuero+accesorios+hilo por unidad.

Sheet Motor_Puntajes
A1: Puntaje interno | B1: Valor (suma de aportes) | C1: Escala | D1: Nivel resultante
A2: CALIDAD POR LOTE (detalle)
A3: Puntaje Calidad - Lote 1 | B3: =Lotes_Produccion!I2 -> 0 | C3: =IF(Lotes_Produccion!B2="","","Segmento: "&Lotes_Produccion!B2) | D3: =Lotes_Produccion!K2
A4: Puntaje Calidad - Lote 2 | B4: =Lotes_Produccion!I3 -> 0 | C4: =IF(Lotes_Produccion!B3="","","Segmento: "&Lotes_Produccion!B3) | D4: =Lotes_Produccion!K3
A5: Puntaje Calidad - Lote 3 | B5: =Lotes_Produccion!I4 -> 0 | C5: =IF(Lotes_Produccion!B4="","","Segmento: "&Lotes_Produccion!B4) | D5: =Lotes_Produccion!K4
A6: Puntaje Calidad EMPRESA (promedio ponderado por unidades) | B6: =IFERROR(SUMPRODUCT(Lotes_Produccion!C2:C4,Lotes_Produccion!I2:I4)/SUM(Lotes_Produccion!C2:C4),0) -> 0 | C6: 0 - 10 (referencial) | D6: =IF(B6>=7,"Alto",IF(B6>=4,"Medio","Bajo")) -> Bajo
A8: OTROS PUNTAJES DE EMPRESA
A9: Puntaje de Eficiencia | B9: =MAX(0,MIN(10,SUM(Seleccion_Ciclo0!G2:G15,Seleccion_Ciclo0!G24:G27))) -> 0 | C9: 0 - 10 (referencial) | D9: =IF(B9>=7,"Alto",IF(B9>=4,"Medio","Bajo")) -> Bajo
A10: Puntaje de Reputacion | B10: =MAX(0,MIN(10,SUM(Seleccion_Ciclo0!H2:H15,Seleccion_Ciclo0!H24:H27))) -> 0 | C10: 0 - 10 (referencial) | D10: =IF(B10>=7,"Alto",IF(B10>=4,"Medio","Bajo")) -> Bajo
A11: Puntaje de Salud Financiera | B11: =MAX(0,MIN(10,SUM(Seleccion_Ciclo0!I2:I15,Seleccion_Ciclo0!I24:I27))) -> 0 | C11: 0 - 10 (referencial) | D11: =IF(B11>=7,"Alto",IF(B11>=4,"Medio","Bajo")) -> Bajo
A13: Nota: cada 'Aporte' se define en la hoja Catalogo_Decisiones (columnas H-K) y se suma automaticamente segun lo elegido en Seleccion_Ciclo0.

Sheet Matriz_Consecuencias
A1: ID | B1: Puntaje evaluado | C1: Condicion | D1: Efecto numerico en el juego | E1: Mensaje textual para el jugador
A2: CONS-01 | B2: Calidad | C2: < 7 y Segmento = Premium | D2: Precio de venta -35%, Reputacion -2 | E2: Posicionaste tu marca como premium, pero tus materiales e insumos no lo respaldan. Los clientes se sienten enganados y las devoluciones aumentan.
A3: CONS-02 | B3: Calidad | C3: >= 7 y Segmento = Premium | D3: Precio de venta +40%, Reputacion +2 | E3: Tu producto cumple con los estandares premium. Los clientes perciben el valor y pagan sin problema el precio elevado.
A4: CONS-03 | B4: Eficiencia | C4: < 4 | D4: Produccion real = 70% de lo planeado (retrasos) | E4: Tu equipo no dio abasto con el volumen que planeaste. Hubo retrasos y entregaste menos de lo prometido.
A5: CONS-04 | B5: Reputacion | C5: < 3 durante 2 ciclos seguidos | D5: Demanda -20% | E5: Tu marca empieza a perder terreno. Los clientes prefieren a la competencia.
A6: CONS-05 | B6: Salud Financiera | C6: < 3 | D6: El banco sube la tasa de interes del proximo prestamo | E6: Tu situacion financiera es riesgosa. El banco te ofrece condiciones menos favorables la proxima vez.
A7: CONS-06 | B7: Produccion vs Capacidad | C7: Cantidad producida > capacidad instalada | D7: Retraso de entrega, costo extra por horas extra | E7: Intentaste producir mas de lo que tu planta soporta. Hubo cuellos de botella y tuviste que pagar horas extra para cumplir.
A8: CONS-07 | B8: Produccion vs Demanda | C8: Cantidad producida > demanda real del mercado | D8: Inventario sin vender, costo de almacenaje | E8: Produjiste mas de lo que el mercado te pidio. Te quedaste con inventario sin vender.
A9: CONS-08 | B9: Eficiencia | C9: Jefatura = No y Eficiencia < 5 | D9: Riesgo de descoordinacion: -5% produccion adicional | E9: Sin jefatura que coordine, tu equipo perdio tiempo resolviendo conflictos de tareas.

Sheet Supuestos
A1: ID | B1: Parámetro | C1: Valor / regla | D1: Estado / fundamento
A2: FUENTE | B2: Base autorizada | C2: v16; v18 no disponible | D2: Autorizado por usuario; hash en control
A3: E3 | B3: Precio por segmento | C3: 40–45 /120–200 /220–400; ideales100/250 | D3: Rangos explícitos usuario; defaults42.5/160/250 supuesto
A4: E4 | B4: Mercado | C4: v2; pesos .7/.2/.1,.4/.35/.25,.1/.5/.4;3500/3500/800 | D4: Canónico por usuario
A5: E5 | B5: Empate económico | C5: PrecioScore100 todos; scores acotados0–100 | D5: Regla solicitada
A6: E5e | B6: Demanda no atendida | C6: Se pierde, sin reasignación | D6: Regla solicitada
A7: E5f | B7: Competidores | C7: Solo empresas que produjeron lote en segmento | D7: Regla solicitada; inventario antiguo solo vende si también produce
A8: E6 | B8: Reputación | C8: Catálogo una opción por grupo; clamp0–10, luego CONS01/02 clamp | D8: SUPUESTO para aprobación; publicidad no se cuenta otra vez
A9: E7 | B9: Capacidad | C9: 24d,90%base,+1pp por N3,+4pp jefatura; corte5/7/9,ensamble6/8/12,acabado6/7/10 | D9: Canon CANTIDAD solicitado
A10: E9 | B10: Calidad y puntajes | C10: Tope0–10; Premium<7 CONS01 y>=7 CONS02 | D10: SUPUESTO hueco Premium resuelto
A11: E9 | B11: Personal mixto | C11: Aporte máximo por grupo, no por cada empleado | D11: SUPUESTO para evitar inflar puntajes por volumen
A12: E11 | B12: Canal | C12: Cobertura base1 para física/digital/mixto | D12: SUPUESTO configurable neutral, pendiente aprobación
... A27: REDONDEO | B27: Unidades | C27: ROUND demanda, floor producción; MIN stock; ingresos2decimales | D27: SUPUESTO para consistencia contable

Sheet Oraculo_v19
A1: caso | B1: empresa | C1: segmento | D1: precio | E1: reputacion | F1: calidad0a10 | G1: stock | H1: producido | I1: bajaPrevios | J1: pesoP | K1: pesoR | L1: pesoC | M1: mercado | N1: ideal | O1: precioScore | P1: puntaje | Q1: participacion | R1: demanda | S1: vendidas | T1: factorPrecio | U1: precioEfectivo | V1: ingresos | W1: demandaPerdida | X1: reputacionFinal
A2: normal_economico | B2: A | C2: SEG-01 | D2: 40 | E2: 7 | F2: 8 | G2: 1000 | H2: 100 | I2: 0 | J2: 0.7 | K2: 0.2 | L2: 0.1 | M2: 3500 | N2: 0 | O2: =IF(H2<=0,0,MAX(0,MIN(100,IF(C2="SEG-01",IF(MAX(IF($H$2>0,$D$2,-1E+99),IF($H$3>0,$D$3,-1E+99),IF($H$4>0,$D$4,-1E+99),IF($H$5>0,$D$5,-1E+99))=MIN(IF($H$2>0,$D$2,1E+99),IF($H$3>0,$D$3,1E+99),IF($H$4>0,$D$4,1E+99),IF($H$5>0,$D$5,1E+99)),100,100*(MAX(IF($H$2>0,$D$2,-1E+99),IF($H$3>0,$D$3,-1E+99),IF($H$4>0,$D$4,-1E+99),IF($H$5>0,$D$5,-1E+99))-D2)/(MAX(IF($H$2>0,$D$2,-1E+99),IF($H$3>0,$D$3,-1E+99),IF($H$4>0,$D$4,-1E+99),IF($H$5>0,$D$5,-1E+99))-MIN(IF($H$2>0,$D$2,1E+99),IF($H$3>0,$D$3,1E+99),IF($H$4>0,$D$4,1E+99),IF($H$5>0,$D$5,1E+99)))),100-ABS(D2-N2)/IF(N2=0,1,N2)*100)))) -> 100 | P2: =IF(H2>0,J2*O2+K2*X2*10+L2*MAX(0,MIN(10,F2))*10,0) -> 92 | Q2: =IFERROR(P2/SUM($P$2:$P$5),0) -> 0.4 | R2: =ROUNDDOWN(ROUND(Q2*M2,0)*IF(AND(X2<3,I2>=1),0.8,1),0) -> 1400 | S2: =MIN(G2,R2) -> 1000 | T2: =IF(C2="SEG-03",IF(F2<7,0.65,1.4),1) -> 1 | U2: =D2*T2 -> 40 | V2: =ROUND(S2*U2,2) -> 40000 | W2: =MAX(0,R2-S2) -> 400 | X2: =MAX(0,MIN(10,E2+IF(C2="SEG-03",IF(F2<7,-2,2),0))) -> 7
A3: normal_economico | B3: B | C3: SEG-01 | D3: 42 | E3: 8 | F3: 7 | G3: 1000 | H3: 100 | I3: 0 | J3: 0.7 | K3: 0.2 | L3: 0.1 | M3: 3500 | N3: 0 | O3: =IF(H3<=0,0,MAX(0,MIN(100,IF(C3="SEG-01",IF(MAX(IF($H$2>0,$D$2,-1E+99),IF($H$3>0,$D$3,-1E+99),IF($H$4>0,$D$4,-1E+99),IF($H$5>0,$D$5,-1E+99))=MIN(IF($H$2>0,$D$2,1E+99),IF($H$3>0,$D$3,1E+99),IF($H$4>0,$D$4,1E+99),IF($H$5>0,$D$5,1E+99)),100,100*(MAX(IF($H$2>0,$D$2,-1E+99),IF($H$3>0,$D$3,-1E+99),IF($H$4>0,$D$4,-1E+99),IF($H$5>0,$D$5,-1E+99))-D3)/(MAX(IF($H$2>0,$D$2,-1E+99),IF($H$3>0,$D$3,-1E+99),IF($H$4>0,$D$4,-1E+99),IF($H$5>0,$D$5,-1E+99))-MIN(IF($H$2>0,$D$2,1E+99),IF($H$3>0,$D$3,1E+99),IF($H$4>0,$D$4,1E+99),IF($H$5>0,$D$5,1E+99)))),100-ABS(D3-N3)/IF(N3=0,1,N3)*100)))) -> 60 | P3: =IF(H3>0,J3*O3+K3*X3*10+L3*MAX(0,MIN(10,F3))*10,0) -> 65 | Q3: =IFERROR(P3/SUM($P$2:$P$5),0) -> 0.2826087 | R3: =ROUNDDOWN(ROUND(Q3*M3,0)*IF(AND(X3<3,I3>=1),0.8,1),0) -> 989 | S3: =MIN(G3,R3) -> 989 | T3: =IF(C3="SEG-03",IF(F3<7,0.65,1.4),1) -> 1 | U3: =D3*T3 -> 42 | V3: =ROUND(S3*U3,2) -> 41538 | W3: =MAX(0,R3-S3) -> 0 | X3: =MAX(0,MIN(10,E3+IF(C3="SEG-03",IF(F3<7,-2,2),0))) -> 8
A4: normal_economico | B4: C | C4: SEG-01 | D4: 43 | E4: 9 | F4: 9 | G4: 1000 | H4: 100 | I4: 0 | J4: 0.7 | K4: 0.2 | L4: 0.1 | M4: 3500 | N4: 0 | O4: =IF(H4<=0,0,MAX(0,MIN(100,IF(C4="SEG-01",IF(MAX(IF($H$2>0,$D$2,-1E+99),IF($H$3>0,$D$3,-1E+99),IF($H$4>0,$D$4,-1E+99),IF($H$5>0,$D$5,-1E+99))=MIN(IF($H$2>0,$D$2,1E+99),IF($H$3>0,$D$3,1E+99),IF($H$4>0,$D$4,1E+99),IF($H$5>0,$D$5,1E+99)),100,100*(MAX(IF($H$2>0,$D$2,-1E+99),IF($H$3>0,$D$3,-1E+99),IF($H$4>0,$D$4,-1E+99),IF($H$5>0,$D$5,-1E+99))-D4)/(MAX(IF($H$2>0,$D$2,-1E+99),IF($H$3>0,$D$3,-1E+99),IF($H$4>0,$D$4,-1E+99),IF($H$5>0,$D$5,-1E+99))-MIN(IF($H$2>0,$D$2,1E+99),IF($H$3>0,$D$3,1E+99),IF($H$4>0,$D$4,1E+99),IF($H$5>0,$D$5,1E+99)))),100-ABS(D4-N4)/IF(N4=0,1,N4)*100)))) -> 40 | P4: =IF(H4>0,J4*O4+K4*X4*10+L4*MAX(0,MIN(10,F4))*10,0) -> 55 | Q4: =IFERROR(P4/SUM($P$2:$P$5),0) -> 0.23913043 | R4: =ROUNDDOWN(ROUND(Q4*M4,0)*IF(AND(X4<3,I4>=1),0.8,1),0) -> 837 | S4: =MIN(G4,R4) -> 837 | T4: =IF(C4="SEG-03",IF(F4<7,0.65,1.4),1) -> 1 | U4: =D4*T4 -> 43 | V4: =ROUND(S4*U4,2) -> 35991 | W4: =MAX(0,R4-S4) -> 0 | X4: =MAX(0,MIN(10,E4+IF(C4="SEG-03",IF(F4<7,-2,2),0))) -> 9
A5: normal_economico | B5: D | C5: SEG-01 | D5: 45 | E5: 6 | F5: 6 | G5: 1000 | H5: 100 | I5: 0 | J5: 0.7 | K5: 0.2 | L5: 0.1 | M5: 3500 | N5: 0 | O5: =IF(H5<=0,0,MAX(0,MIN(100,IF(C5="SEG-01",IF(MAX(IF($H$2>0,$D$2,-1E+99),IF($H$3>0,$D$3,-1E+99),IF($H$4>0,$D$4,-1E+99),IF($H$5>0,$D$5,-1E+99))=MIN(IF($H$2>0,$D$2,1E+99),IF($H$3>0,$D$3,1E+99),IF($H$4>0,$D$4,1E+99),IF($H$5>0,$D$5,1E+99)),100,100*(MAX(IF($H$2>0,$D$2,-1E+99),IF($H$3>0,$D$3,-1E+99),IF($H$4>0,$D$4,-1E+99),IF($H$5>0,$D$5,-1E+99))-D5)/(MAX(IF($H$2>0,$D$2,-1E+99),IF($H$3>0,$D$3,-1E+99),IF($H$4>0,$D$4,-1E+99),IF($H$5>0,$D$5,-1E+99))-MIN(IF($H$2>0,$D$2,1E+99),IF($H$3>0,$D$3,1E+99),IF($H$4>0,$D$4,1E+99),IF($H$5>0,$D$5,1E+99)))),100-ABS(D5-N5)/IF(N5=0,1,N5)*100)))) -> 0 | P5: =IF(H5>0,J5*O5+K5*X5*10+L5*MAX(0,MIN(10,F5))*10,0) -> 18 | Q5: =IFERROR(P5/SUM($P$2:$P$5),0) -> 0.07826087 | R5: =ROUNDDOWN(ROUND(Q5*M5,0)*IF(AND(X5<3,I5>=1),0.8,1),0) -> 274 | S5: =MIN(G5,R5) -> 274 | T5: =IF(C5="SEG-03",IF(F5<7,0.65,1.4),1) -> 1 | U5: =D5*T5 -> 45 | V5: =ROUND(S5*U5,2) -> 12330 | W5: =MAX(0,R5-S5) -> 0 | X5: =MAX(0,MIN(10,E5+IF(C5="SEG-03",IF(F5<7,-2,2),0))) -> 6
A6: normal_medio | B6: A | C6: SEG-02 | D6: 120 | E6: 7 | F6: 8 | G6: 1000 | H6: 100 | I6: 0 | J6: 0.4 | K6: 0.35 | L6: 0.25 | M6: 3500 | N6: 100 | O6: =IF(H6<=0,0,MAX(0,MIN(100,IF(C6="SEG-01",IF(MAX(IF($H$6>0,$D$6,-1E+99),IF($H$7>0,$D$7,-1E+99),IF($H$8>0,$D$8,-1E+99),IF($H$9>0,$D$9,-1E+99))=MIN(IF($H$6>0,$D$6,1E+99),IF($H$7>0,$D$7,1E+99),IF($H$8>0,$D$8,1E+99),IF($H$9>0,$D$9,1E+99)),100,100*(MAX(IF($H$6>0,$D$6,-1E+99),IF($H$7>0,$D$7,-1E+99),IF($H$8>0,$D$8,-1E+99),IF($H$9>0,$D$9,-1E+99))-D6)/(MAX(IF($H$6>0,$D$6,-1E+99),IF($H$7>0,$D$7,-1E+99),IF($H$8>0,$D$8,-1E+99),IF($H$9>0,$D$9,-1E+99))-MIN(IF($H$6>0,$D$6,1E+99),IF($H$7>0,$D$7,1E+99),IF($H$8>0,$D$8,1E+99),IF($H$9>0,$D$9,1E+99)))),100-ABS(D6-N6)/IF(N6=0,1,N6)*100)))) -> 80 | P6: =IF(H6>0,J6*O6+K6*X6*10+L6*MAX(0,MIN(10,F6))*10,0) -> 76.5 | Q6: =IFERROR(P6/SUM($P$6:$P$9),0) -> 0.30357143 | R6: =ROUNDDOWN(ROUND(Q6*M6,0)*IF(AND(X6<3,I6>=1),0.8,1),0) -> 1063 | S6: =MIN(G6,R6) -> 1000 | T6: =IF(C6="SEG-03",IF(F6<7,0.65,1.4),1) -> 1 | U6: =D6*T6 -> 120 | V6: =ROUND(S6*U6,2) -> 120000 | W6: =MAX(0,R6-S6) -> 63 | X6: =MAX(0,MIN(10,E6+IF(C6="SEG-03",IF(F6<7,-2,2),0))) -> 7
A7: normal_medio | B7: B | C7: SEG-02 | D7: 140 | E7: 8 | F7: 7 | G7: 1000 | H7: 100 | I7: 0 | J7: 0.4 | K7: 0.35 | L7: 0.25 | M7: 3500 | N7: 100 | O7: =IF(H7<=0,0,MAX(0,MIN(100,IF(C7="SEG-01",IF(MAX(IF($H$6>0,$D$6,-1E+99),IF($H$7>0,$D$7,-1E+99),IF($H$8>0,$D$8,-1E+99),IF($H$9>0,$D$9,-1E+99))=MIN(IF($H$6>0,$D$6,1E+99),IF($H$7>0,$D$7,1E+99),IF($H$8>0,$D$8,1E+99),IF($H$9>0,$D$9,1E+99)),100,100*(MAX(IF($H$6>0,$D$6,-1E+99),IF($H$7>0,$D$7,-1E+99),IF($H$8>0,$D$8,-1E+99),IF($H$9>0,$D$9,-1E+99))-D7)/(MAX(IF($H$6>0,$D$6,-1E+99),IF($H$7>0,$D$7,-1E+99),IF($H$8>0,$D$8,-1E+99),IF($H$9>0,$D$9,-1E+99))-MIN(IF($H$6>0,$D$6,1E+99),IF($H$7>0,$D$7,1E+99),IF($H$8>0,$D$8,1E+99),IF($H$9>0,$D$9,1E+99)))),100-ABS(D7-N7)/IF(N7=0,1,N7)*100)))) -> 60 | P7: =IF(H7>0,J7*O7+K7*X7*10+L7*MAX(0,MIN(10,F7))*10,0) -> 69.5 | Q7: =IFERROR(P7/SUM($P$6:$P$9),0) -> 0.27579365 | R7: =ROUNDDOWN(ROUND(Q7*M7,0)*IF(AND(X7<3,I7>=1),0.8,1),0) -> 965 | S7: =MIN(G7,R7) -> 965 | T7: =IF(C7="SEG-03",IF(F7<7,0.65,1.4),1) -> 1 | U7: =D7*T7 -> 140 | V7: =ROUND(S7*U7,2) -> 135100 | W7: =MAX(0,R7-S7) -> 0 | X7: =MAX(0,MIN(10,E7+IF(C7="SEG-03",IF(F7<7,-2,2),0))) -> 8
A8: normal_medio | B8: C | C8: SEG-02 | D8: 160 | E8: 9 | F8: 9 | G8: 1000 | H8: 100 | I8: 0 | J8: 0.4 | K8: 0.35 | L8: 0.25 | M8: 3500 | N8: 100 | O8: =IF(H8<=0,0,MAX(0,MIN(100,IF(C8="SEG-01",IF(MAX(IF($H$6>0,$D$6,-1E+99),IF($H$7>0,$D$7,-1E+99),IF($H$8>0,$D$8,-1E+99),IF($H$9>0,$D$9,-1E+99))=MIN(IF($H$6>0,$D$6,1E+99),IF($H$7>0,$D$7,1E+99),IF($H$8>0,$D$8,1E+99),IF($H$9>0,$D$9,1E+99)),100,100*(MAX(IF($H$6>0,$D$6,-1E+99),IF($H$7>0,$D$7,-1E+99),IF($H$8>0,$D$8,-1E+99),IF($H$9>0,$D$9,-1E+99))-D8)/(MAX(IF($H$6>0,$D$6,-1E+99),IF($H$7>0,$D$7,-1E+99),IF($H$8>0,$D$8,-1E+99),IF($H$9>0,$D$9,-1E+99))-MIN(IF($H$6>0,$D$6,1E+99),IF($H$7>0,$D$7,1E+99),IF($H$8>0,$D$8,1E+99),IF($H$9>0,$D$9,1E+99)))),100-ABS(D8-N8)/IF(N8=0,1,N8)*100)))) -> 40 | P8: =IF(H8>0,J8*O8+K8*X8*10+L8*MAX(0,MIN(10,F8))*10,0) -> 70 | Q8: =IFERROR(P8/SUM($P$6:$P$9),0) -> 0.27777778 | R8: =ROUNDDOWN(ROUND(Q8*M8,0)*IF(AND(X8<3,I8>=1),0.8,1),0) -> 972 | S8: =MIN(G8,R8) -> 972 | T8: =IF(C8="SEG-03",IF(F8<7,0.65,1.4),1) -> 1 | U8: =D8*T8 -> 160 | V8: =ROUND(S8*U8,2) -> 155520 | W8: =MAX(0,R8-S8) -> 0 | X8: =MAX(0,MIN(10,E8+IF(C8="SEG-03",IF(F8<7,-2,2),0))) -> 9
